Workbook

Sheet taXel全体
A1: 全社PL | J1: =IFERROR(I5/E5,"-") -> 21.732568 | K1: =IF(K5>0,K5/J5,"-") -> - | L1: =IF(L5>0,L5/K5,"-") -> - | M1: =IF(M5>0,M5/L5,"-") -> - | N1: =IF(N5>0,N5/M5,"-") -> -
E2: Y1 | F2: Y2 | G2: Y3 | H2: Y4 | I2: Y5 | J2: 5カ年 | P2: 実績 | Q2: 実績 | R2: 実績 | S2: 実績 | T2: 実績 | U2: 実績 | V2: 実績 | W2: 実績 | X2: 実績 | Y2: 実績 | Z2: 実績 | AA2: 実績 | AB2: M1 | AC2: M2 | AD2: M3 | AE2: M4 | AF2: M5 | AG2: M6 | AH2: M7 | AI2: M8 | AJ2: M9 | AK2: M10 | AL2: M11 | AM2: M12 | AN2: M13 | AO2: M1４ | AP2: M15 | AQ2: M16 | AR2: M17 | AS2: M18 | AT2: M19 | AU2: M20 | AV2: M21 | AW2: M22 | AX2: M23 | AY2: M24 | AZ2: M25 | BA2: M26 | BB2: M27 | BC2: M28 | BD2: M29 | BE2: M30 | BF2: M31 | BG2: M32 | BH2: M33 | BI2: M34 | BJ2: M35 | BK2: M36 | BL2: M37 | BM2: M38 | BN2: M39 | BO2: M40 | BP2: M41 | BQ2: M42 | BR2: M43 | BS2: M44 | BT2: M45 | BU2: M46 | BV2: M47 | BW2: M48 | BX2: M49 | BY2: M50 | BZ2: M51 | CA2: M52 | CB2: M53 | CC2: M54 | CD2: M55 | CE2: M56 | CF2: M57 | CG2: M58 | CH2: M59 | CI2: M60
E3: 計画 | F3: 計画 | G3: 計画 | H3: 計画 | I3: 計画 | J3: 計画 | K3: 計画 | L3: 計画 | M3: 計画 | N3: 計画 | P3: 22年6月期 | Q3: 22年6月期 | R3: 22年6月期 | S3: 22年6月期 | T3: 22年6月期 | U3: 22年6月期 | V3: 22年6月期 | W3: 22年6月期 | X3: 22年6月期 | Y3: 22年6月期 | Z3: 22年6月期 | AA3: 22年6月期 | AB3: 23年6月期 | AC3: 23年6月期 | AD3: 23年6月期 | AE3: 23年6月期 | AF3: 23年6月期 | AG3: 23年6月期 | AH3: 23年6月期 | AI3: 23年6月期 | AJ3: 23年6月期 | AK3: 23年6月期 | AL3: 23年6月期 | AM3: 23年6月期 | AN3: 24年6月期 | AO3: 24年6月期 | AP3: 24年6月期 | AQ3: 24年6月期 | AR3: 24年6月期 | AS3: 24年6月期 | AT3: 24年6月期 | AU3: 24年6月期 | AV3: 24年6月期 | AW3: 24年6月期 | AX3: 24年6月期 | AY3: 24年6月期 | AZ3: 25年6月期 | BA3: 25年6月期 | BB3: 25年6月期 | BC3: 25年6月期 | BD3: 25年6月期 | BE3: 25年6月期 | BF3: 25年6月期 | BG3: 25年6月期 | BH3: 25年6月期 | BI3: 25年6月期 | BJ3: 25年6月期 | BK3: 25年6月期 | BL3: 26年6月期 | BM3: 26年6月期 | BN3: 26年6月期 | BO3: 26年6月期 | BP3: 26年6月期 | BQ3: 26年6月期 | BR3: 26年6月期 | BS3: 26年6月期 | BT3: 26年6月期 | BU3: 26年6月期 | BV3: 26年6月期 | BW3: 26年6月期 | BX3: 27年6月期 | BY3: 27年6月期 | BZ3: 27年6月期 | CA3: 27年6月期 | CB3: 27年6月期 | CC3: 27年6月期 | CD3: 27年6月期 | CE3: 27年6月期 | CF3: 27年6月期 | CG3: 27年6月期 | CH3: 27年6月期 | CI3: 27年6月期
C4: Ref. | E4: =AB3 -> 23年6月期 | F4: =AN3 -> 24年6月期 | G4: =AZ3 -> 25年6月期 | H4: =BL3 -> 26年6月期 | I4: =BX3 -> 27年6月期 | J4: 5カ年合計 | K4: 29年6月期 | L4: 30年6月期 | M4: 31年6月期 | N4: 32年6月期 | P4: 21年7月 | Q4: 21年8月 | R4: 21年9月 | S4: 21年10月 | T4: 21年11月 | U4: 21年12月 | V4: 22年1月 | W4: 22年2月 | X4: 22年3月 | Y4: 22年4月 | Z4: 22年5月 | AA4: 22年6月 | AB4: 22年7月 | AC4: 22年8月 | AD4: 22年9月 | AE4: 22年10月 | AF4: 22年11月 | AG4: 22年12月 | AH4: 23年1月 | AI4: 23年2月 | AJ4: 23年3月 | AK4: 23年4月 | AL4: 23年5月 | AM4: 23年6月 | AN4: 23年7月 | AO4: 23年8月 | AP4: 23年9月 | AQ4: 23年10月 | AR4: 23年11月 | AS4: 23年12月 | AT4: 24年1月 | AU4: 24年2月 | AV4: 24年3月 | AW4: 24年4月 | AX4: 24年5月 | AY4: 24年6月 | AZ4: 24年7月 | BA4: 24年8月 | BB4: 24年9月 | BC4: 24年10月 | BD4: 24年11月 | BE4: 24年12月 | BF4: 25年1月 | BG4: 25年2月 | BH4: 25年3月 | BI4: 25年4月 | BJ4: 25年5月 | BK4: 25年6月 | BL4: 25年7月 | BM4: 25年8月 | BN4: 25年9月 | BO4: 25年10月 | BP4: 25年11月 | BQ4: 25年12月 | BR4: 26年1月 | BS4: 26年2月 | BT4: 26年3月 | BU4: 26年4月 | BV4: 26年5月 | BW4: 26年6月 | BX4: 26年7月 | BY4: 26年8月 | BZ4: 26年9月 | CA4: 26年10月 | CB4: 26年11月 | CC4: 26年12月 | CD4: 27年1月 | CE4: 27年2月 | CF4: 27年3月 | CG4: 27年4月 | CH4: 27年5月 | CI4: 27年6月
A5: 売上高 | C5: TaXel 全体 | D5: 円 | E5: =SUM(E6:E12) -> 23100792 | F5: =SUM(F6:F12) -> 1.0759832e+08 | G5: =SUM(G6:G12) -> 2.17985e+08 | H5: =SUM(H6:H12) -> 3.470612e+08 | I5: =SUM(I6:I12) -> 5.0203953e+08 | J5: =SUM(E5:I5) -> 1.1977848e+09 | K5: =SUMIF($P$3:$CN$3,K$4,$P5:$CN5) -> 0 | L5: =SUMIF($P$3:$CN$3,L$4,$P5:$CN5) -> 0 | M5: =SUMIF($P$3:$CN$3,M$4,$P5:$CN5) -> 0 | N5: =SUMIF($P$3:$CN$3,N$4,$P5:$CN5) -> 0 | P5: =SUM(P6) -> 0 | Q5: =SUM(Q6) -> 0 | R5: =SUM(R6) -> 0 | S5: =SUM(S6) -> 0 | T5: =SUM(T6) -> 0 | U5: =SUM(U6) -> 0 | V5: =SUM(V6) -> 0 | W5: =SUM(W6) -> 0 | ... AA5: =SUM(AA6) -> 0 | AB5: =SUM(AB6:AB12) -> 0 | AC5: =SUM(AC6:AC12) -> 56598.421 | AD5: =SUM(AD6:AD12) -> 331721.39 | AE5: =SUM(AE6:AE12) -> 601899.77 | AF5: =SUM(AF6:AF12) -> 860371.3 | AG5: =SUM(AG6:AG12) -> 1170767.7 | AH5: =SUM(AH6:AH12) -> 1805576 | AI5: =SUM(AI6:AI12) -> 2434908 | ... CI5: =SUM(CI6:CI12) -> 48484711
B6: SaaS事業 | C6: SaaS | E6: =SUMIF($AB$3:$CI$3,E$4,$AB6:$CI6) -> 13155039 | F6: =SUMIF($AB$3:$CI$3,F$4,$AB6:$CI6) -> 54970475 | G6: =SUMIF($AB$3:$CI$3,G$4,$AB6:$CI6) -> 1.1300102e+08 | H6: =SUMIF($AB$3:$CI$3,H$4,$AB6:$CI6) -> 1.8562995e+08 | I6: =SUMIF($AB$3:$CI$3,I$4,$AB6:$CI6) -> 2.7676127e+08 | J6: =SUM(E6:I6) -> 6.4351776e+08 | K6: =SUMIF($P$3:$CN$3,K$4,$P6:$CN6) -> 0 | L6: =SUMIF($P$3:$CN$3,L$4,$P6:$CN6) -> 0 | M6: =SUMIF($P$3:$CN$3,M$4,$P6:$CN6) -> 0 | N6: =SUMIF($P$3:$CN$3,N$4,$P6:$CN6) -> 0 | AB6: =SaaS!F5 -> 0 | AC6: =SaaS!G5 -> 42876.146 | AD6: =SaaS!H5 -> 256399.35 | AE6: =SaaS!I5 -> 465652.1 | AF6: =SaaS!J5 -> 670719.79 | AG6: =SaaS!K5 -> 914562.27 | AH6: =SaaS!L5 -> 1153527.9 | AI6: =SaaS!M5 -> 1387714.2 | ... CI6: =SaaS!BM5 -> 27073469
B7: コンサルティング事業 | C7: 事業・組織再生コンサル | E7: =SUMIF($AB$3:$CI$3,E$4,$AB7:$CI7) -> 6270000 | F7: =SUMIF($AB$3:$CI$3,F$4,$AB7:$CI7) -> 37950000 | G7: =SUMIF($AB$3:$CI$3,G$4,$AB7:$CI7) -> 75900000 | H7: =SUMIF($AB$3:$CI$3,H$4,$AB7:$CI7) -> 115170000 | I7: =SUMIF($AB$3:$CI$3,I$4,$AB7:$CI7) -> 157740000 | J7: =SUM(E7:I7) -> 393030000 | K7: =SUMIF($P$3:$CN$3,K$4,$P7:$CN7) -> 0 | L7: =SUMIF($P$3:$CN$3,L$4,$P7:$CN7) -> 0 | M7: =SUMIF($P$3:$CN$3,M$4,$P7:$CN7) -> 0 | N7: =SUMIF($P$3:$CN$3,N$4,$P7:$CN7) -> 0 | AB7: ='事業・組織再生コンサル'!F4 -> 0 | AC7: ='事業・組織再生コンサル'!G4 -> 0 | AD7: ='事業・組織再生コンサル'!H4 -> 0 | AE7: ='事業・組織再生コンサル'!I4 -> 0 | AF7: ='事業・組織再生コンサル'!J4 -> 0 | AG7: ='事業・組織再生コンサル'!K4 -> 0 | AH7: ='事業・組織再生コンサル'!L4 -> 330000 | AI7: ='事業・組織再生コンサル'!M4 -> 660000 | ... CI7: ='事業・組織再生コンサル'!BM4 -> 14850000
B8: 紹介事業 | C8: ビジとり | E8: =SUMIF($AB$3:$CI$3,E$4,$AB8:$CI8) -> 503095.67 | F8: =SUMIF($AB$3:$CI$3,F$4,$AB8:$CI8) -> 1927248.6 | G8: =SUMIF($AB$3:$CI$3,G$4,$AB8:$CI8) -> 3683882 | H8: =SUMIF($AB$3:$CI$3,H$4,$AB8:$CI8) -> 5663952.8 | I8: =SUMIF($AB$3:$CI$3,I$4,$AB8:$CI8) -> 8073839.8 | J8: =SUM(E8:I8) -> 19852019 | K8: =SUMIF($P$3:$CN$3,K$4,$P8:$CN8) -> 0 | L8: =SUMIF($P$3:$CN$3,L$4,$P8:$CN8) -> 0 | M8: =SUMIF($P$3:$CN$3,M$4,$P8:$CN8) -> 0 | N8: =SUMIF($P$3:$CN$3,N$4,$P8:$CN8) -> 0 | AB8: =ビジとり!F5 -> 0 | AC8: =ビジとり!G5 -> 1929.375 | AD8: =ビジとり!H5 -> 10572.975 | AE8: =ビジとり!I5 -> 19043.703 | AF8: =ビジとり!J5 -> 26380.329 | AG8: =ビジとり!K5 -> 35499.597 | AH8: =ビジとり!L5 -> 44436.48 | AI8: =ビジとり!M5 -> 53194.626 | ... CI8: =ビジとり!BM5 -> 778105.88
B9: 紹介事業 | C9: 支払い.com | E9: =SUMIF($AB$3:$CI$3,E$4,$AB9:$CI9) -> 1036460.2 | F9: =SUMIF($AB$3:$CI$3,F$4,$AB9:$CI9) -> 4331391.8 | G9: =SUMIF($AB$3:$CI$3,G$4,$AB9:$CI9) -> 8900813.2 | H9: =SUMIF($AB$3:$CI$3,H$4,$AB9:$CI9) -> 14619150 | I9: =SUMIF($AB$3:$CI$3,I$4,$AB9:$CI9) -> 21803150 | J9: =SUM(E9:I9) -> 50690966 | K9: =SUMIF($P$3:$CN$3,K$4,$P9:$CN9) -> 0 | L9: =SUMIF($P$3:$CN$3,L$4,$P9:$CN9) -> 0 | M9: =SUMIF($P$3:$CN$3,M$4,$P9:$CN9) -> 0 | N9: =SUMIF($P$3:$CN$3,N$4,$P9:$CN9) -> 0 | AB9: ='支払い.com'!F5 -> 0 | AC9: ='支払い.com'!G5 -> 3748.5 | AD9: ='支払い.com'!H5 -> 20616.75 | AE9: ='支払い.com'!I5 -> 37485 | AF9: ='支払い.com'!J5 -> 52479 | AG9: ='支払い.com'!K5 -> 71221.5 | AH9: ='支払い.com'!L5 -> 89964 | AI9: ='支払い.com'!M5 -> 108706.5 | ... CI9: ='支払い.com'!BM5 -> 2132896.5
B10: 仲介事業 | C10: プライペートバンク仲介 | E10: =SUMIF($AB$3:$CI$3,E$4,$AB10:$CI10) -> 473115.28 | F10: =SUMIF($AB$3:$CI$3,F$4,$AB10:$CI10) -> 1812400.3 | G10: =SUMIF($AB$3:$CI$3,G$4,$AB10:$CI10) -> 3464352.7 | H10: =SUMIF($AB$3:$CI$3,H$4,$AB10:$CI10) -> 5326427.4 | I10: =SUMIF($AB$3:$CI$3,I$4,$AB10:$CI10) -> 7592704.8 | J10: =SUM(E10:I10) -> 18669001 | K10: =SUMIF($P$3:$CN$3,K$4,$P10:$CN10) -> 0 | L10: =SUMIF($P$3:$CN$3,L$4,$P10:$CN10) -> 0 | M10: =SUMIF($P$3:$CN$3,M$4,$P10:$CN10) -> 0 | N10: =SUMIF($P$3:$CN$3,N$4,$P10:$CN10) -> 0 | AB10: =PB!F5 -> 0 | AC10: =PB!G5 -> 1814.4 | AD10: =PB!H5 -> 9942.912 | AE10: =PB!I5 -> 17908.854 | AF10: =PB!J5 -> 24808.277 | AG10: =PB!K5 -> 33384.111 | AH10: =PB!L5 -> 41788.429 | AI10: =PB!M5 -> 50024.66 | ... CI10: =PB!BM5 -> 731737.12
B11: 紹介事業 | C11: 電力コスト削減 | E11: =SUMIF($AB$3:$CI$3,E$4,$AB11:$CI11) -> 677425 | F11: =SUMIF($AB$3:$CI$3,F$4,$AB11:$CI11) -> 2830975 | G11: =SUMIF($AB$3:$CI$3,G$4,$AB11:$CI11) -> 5817525 | H11: =SUMIF($AB$3:$CI$3,H$4,$AB11:$CI11) -> 9555000 | I11: =SUMIF($AB$3:$CI$3,I$4,$AB11:$CI11) -> 14250425 | J11: =SUM(E11:I11) -> 33131350 | K11: =SUMIF($P$3:$CN$3,K$4,$P11:$CN11) -> 0 | L11: =SUMIF($P$3:$CN$3,L$4,$P11:$CN11) -> 0 | M11: =SUMIF($P$3:$CN$3,M$4,$P11:$CN11) -> 0 | N11: =SUMIF($P$3:$CN$3,N$4,$P11:$CN11) -> 0 | AB11: =電力コスト削減!F5 -> 0 | AC11: =電力コスト削減!G5 -> 2450 | AD11: =電力コスト削減!H5 -> 13475 | AE11: =電力コスト削減!I5 -> 24500 | AF11: =電力コスト削減!J5 -> 34300 | AG11: =電力コスト削減!K5 -> 46550 | AH11: =電力コスト削減!L5 -> 58800 | AI11: =電力コスト削減!M5 -> 71050 | ... CI11: =電力コスト削減!BM5 -> 1394050
B12: 紹介事業 | C12: 売掛金 | E12: =SUMIF($AB$3:$CI$3,E$4,$AB12:$CI12) -> 985656.83 | F12: =SUMIF($AB$3:$CI$3,F$4,$AB12:$CI12) -> 3775834 | G12: =SUMIF($AB$3:$CI$3,G$4,$AB12:$CI12) -> 7217401.4 | H12: =SUMIF($AB$3:$CI$3,H$4,$AB12:$CI12) -> 11096724 | I12: =SUMIF($AB$3:$CI$3,I$4,$AB12:$CI12) -> 15818135 | J12: =SUM(E12:I12) -> 38893751 | K12: =SUMIF($P$3:$CN$3,K$4,$P12:$CN12) -> 0 | L12: =SUMIF($P$3:$CN$3,L$4,$P12:$CN12) -> 0 | M12: =SUMIF($P$3:$CN$3,M$4,$P12:$CN12) -> 0 | N12: =SUMIF($P$3:$CN$3,N$4,$P12:$CN12) -> 0 | AB12: =' 売掛保証（保証型ファクタリング'!F5 -> 0 | AC12: =' 売掛保証（保証型ファクタリング'!G5 -> 3780 | AD12: =' 売掛保証（保証型ファクタリング'!H5 -> 20714.4 | AE12: =' 売掛保証（保証型ファクタリング'!I5 -> 37310.112 | AF12: =' 売掛保証（保証型ファクタリング'!J5 -> 51683.91 | AG12: =' 売掛保証（保証型ファクタリング'!K5 -> 69550.232 | AH12: =' 売掛保証（保証型ファクタリング'!L5 -> 87059.227 | AI12: =' 売掛保証（保証型ファクタリング'!M5 -> 104218.04 | ... CI12: =' 売掛保証（保証型ファクタリング'!BM5 -> 1524452.3
C13: 前期比 | D13: ％ | F13: =IF(E5>0,(F5-E5)/E5,"-") -> 3.6577764 | G13: =IF(F5>0,(G5-F5)/F5,"-") -> 1.0259144 | H13: =IF(G5>0,(H5-G5)/G5,"-") -> 0.59213344 | I13: =IF(H5>0,(I5-H5)/H5,"-") -> 0.44654465 | J13: =IFERROR((I5/E5)^(1/4)-1,"-") -> 1.1591249 | K13: =IF(K5>0,(K5-J5)/J5,"-") -> - | L13: =IF(L5>0,(L5-K5)/K5,"-") -> - | M13: =IF(M5>0,(M5-L5)/L5,"-") -> - | N13: =IF(N5>0,(N5-M5)/M5,"-") -> -
A14: 売上原価 | C14: COGS合計 | D14: 円 | E14: =SUMIF($AB$3:$CI$3,E$4,$AB14:$CI14) -> 1950363.2 | F14: =SUMIF($AB$3:$CI$3,F$4,$AB14:$CI14) -> 8004320.5 | G14: =SUMIF($AB$3:$CI$3,G$4,$AB14:$CI14) -> 16231490 | H14: =SUMIF($AB$3:$CI$3,H$4,$AB14:$CI14) -> 26316703 | I14: =SUMIF($AB$3:$CI$3,I$4,$AB14:$CI14) -> 39109407 | J14: =SUM(E14:I14) -> 91612284 | K14: =SUMIF($P$3:$CN$3,K$4,$P14:$CN14) -> 0 | L14: =SUMIF($P$3:$CN$3,L$4,$P14:$CN14) -> 0 | M14: =SUMIF($P$3:$CN$3,M$4,$P14:$CN14) -> 0 | N14: =SUMIF($P$3:$CN$3,N$4,$P14:$CN14) -> 0 | AB14: =SUM(AB17:AB20) -> 50000 | AC14: =SUM(AC17:AC20) -> 53343.541 | AD14: =SUM(AD17:AD20) -> 69994.377 | AE14: =SUM(AE17:AE20) -> 86312.196 | AF14: =SUM(AF17:AF20) -> 104555.91 | AG14: =SUM(AG17:AG20) -> 134719.72 | AH14: =SUM(AH17:AH20) -> 163945.8 | AI14: =SUM(AI17:AI20) -> 192269.62 | ... CI14: =SUM(CI17:CI20) -> 3652753.3
C15: AIレポート原価（円/社・月） | E15: =SUMIF($AB$3:$CI$3,E$4,$AB15:$CI15)/12 -> 150 | F15: =SUMIF($AB$3:$CI$3,F$4,$AB15:$CI15)/12 -> 150 | G15: =SUMIF($AB$3:$CI$3,G$4,$AB15:$CI15)/12 -> 150 | H15: =SUMIF($AB$3:$CI$3,H$4,$AB15:$CI15)/12 -> 150 | I15: =SUMIF($AB$3:$CI$3,I$4,$AB15:$CI15)/12 -> 150 | J15: =AVERAGE(E15:I15) -> 150 | AB15: =費用予算!F25 -> 150 | AC15: =費用予算!G25 -> 150 | AD15: =費用予算!H25 -> 150 | AE15: =費用予算!I25 -> 150 | AF15: =費用予算!J25 -> 150 | AG15: =費用予算!K25 -> 150 | AH15: =費用予算!L25 -> 150 | AI15: =費用予算!M25 -> 150 | ... CI15: =費用予算!BM25 -> 150
C16: 稼働顧問先数 | E16: =SUMIF($AB$3:$CI$3,E$4,$AB16:$CI16)/12 -> 306.81487 | F16: =SUMIF($AB$3:$CI$3,F$4,$AB16:$CI16)/12 -> 1282.0759 | G16: =SUMIF($AB$3:$CI$3,G$4,$AB16:$CI16)/12 -> 2635.5219 | H16: =SUMIF($AB$3:$CI$3,H$4,$AB16:$CI16)/12 -> 4329.4458 | I16: =SUMIF($AB$3:$CI$3,I$4,$AB16:$CI16)/12 -> 6454.9009 | J16: =AVERAGE(E16:I16) -> 3001.7519 | AB16: =費用予算!F26 -> 0 | AC16: =費用予算!G26 -> 12 | AD16: =費用予算!H26 -> 71.76 | AE16: =費用予算!I26 -> 130.3248 | AF16: =費用予算!J26 -> 187.7183 | AG16: =費用予算!K26 -> 255.96394 | AH16: =費用予算!L26 -> 322.84466 | AI16: =費用予算!M26 -> 388.38777 | ... CI16: =費用予算!BM26 -> 7577.2114
C17: AI API費 | E17: =SUMIF($AB$3:$CI$3,E$4,$AB17:$CI17) -> 552266.76 | F17: =SUMIF($AB$3:$CI$3,F$4,$AB17:$CI17) -> 2307736.7 | G17: =SUMIF($AB$3:$CI$3,G$4,$AB17:$CI17) -> 4743939.4 | H17: =SUMIF($AB$3:$CI$3,H$4,$AB17:$CI17) -> 7793002.4 | I17: =SUMIF($AB$3:$CI$3,I$4,$AB17:$CI17) -> 11618822 | J17: =SUM(E17:I17) -> 27015767 | AB17: =費用予算!F27 -> 0 | AC17: =費用予算!G27 -> 1800 | AD17: =費用予算!H27 -> 10764 | AE17: =費用予算!I27 -> 19548.72 | AF17: =費用予算!J27 -> 28157.746 | AG17: =費用予算!K27 -> 38394.591 | AH17: =費用予算!L27 -> 48426.699 | AI17: =費用予算!M27 -> 58258.165 | ... CI17: =費用予算!BM27 -> 1136581.7
C18: サーバー・DB費 | E18: =SUMIF($AB$3:$CI$3,E$4,$AB18:$CI18) -> 600000 | F18: =SUMIF($AB$3:$CI$3,F$4,$AB18:$CI18) -> 1800000 | G18: =SUMIF($AB$3:$CI$3,G$4,$AB18:$CI18) -> 3600000 | H18: =SUMIF($AB$3:$CI$3,H$4,$AB18:$CI18) -> 6000000 | I18: =SUMIF($AB$3:$CI$3,I$4,$AB18:$CI18) -> 9600000 | J18: =SUM(E18:I18) -> 21600000 | K18: =SUMIF($P$3:$CN$3,K$4,$P18:$CN18) -> 0 | L18: =SUMIF($P$3:$CN$3,L$4,$P18:$CN18) -> 0 | M18: =SUMIF($P$3:$CN$3,M$4,$P18:$CN18) -> 0 | N18: =SUMIF($P$3:$CN$3,N$4,$P18:$CN18) -> 0 | AB18: =費用予算!F28 -> 50000 | AC18: =費用予算!G28 -> 50000 | AD18: =費用予算!H28 -> 50000 | AE18: =費用予算!I28 -> 50000 | AF18: =費用予算!J28 -> 50000 | AG18: =費用予算!K28 -> 50000 | AH18: =費用予算!L28 -> 50000 | AI18: =費用予算!M28 -> 50000 | ... CI18: =費用予算!BM28 -> 800000
C19: 決済手数料 | E19: =SUMIF($AB$3:$CI$3,E$4,$AB19:$CI19) -> 473581.4 | F19: =SUMIF($AB$3:$CI$3,F$4,$AB19:$CI19) -> 1978937.1 | G19: =SUMIF($AB$3:$CI$3,G$4,$AB19:$CI19) -> 4068036.8 | H19: =SUMIF($AB$3:$CI$3,H$4,$AB19:$CI19) -> 6682678.2 | I19: =SUMIF($AB$3:$CI$3,I$4,$AB19:$CI19) -> 9963405.8 | J19: =SUM(E19:I19) -> 23166639 | K19: =SUMIF($P$3:$CN$3,K$4,$P19:$CN19) -> 0 | L19: =SUMIF($P$3:$CN$3,L$4,$P19:$CN19) -> 0 | M19: =SUMIF($P$3:$CN$3,M$4,$P19:$CN19) -> 0 | N19: =SUMIF($P$3:$CN$3,N$4,$P19:$CN19) -> 0 | AB19: =費用予算!F29 -> 0 | AC19: =費用予算!G29 -> 1543.5413 | AD19: =費用予算!H29 -> 9230.3767 | AE19: =費用予算!I29 -> 16763.476 | AF19: =費用予算!J29 -> 24145.912 | AG19: =費用予算!K29 -> 32924.242 | AH19: =費用予算!L29 -> 41527.004 | AI19: =費用予算!M29 -> 49957.712 | ... CI19: =費用予算!BM29 -> 974644.87
C20: コンサル直接経費 | E20: =SUMIF($AB$3:$CI$3,E$4,$AB20:$CI20) -> 324515.06 | F20: =SUMIF($AB$3:$CI$3,F$4,$AB20:$CI20) -> 1917646.7 | G20: =SUMIF($AB$3:$CI$3,G$4,$AB20:$CI20) -> 3819514.2 | H20: =SUMIF($AB$3:$CI$3,H$4,$AB20:$CI20) -> 5841022.4 | I20: =SUMIF($AB$3:$CI$3,I$4,$AB20:$CI20) -> 7927179.9 | J20: =SUM(E20:I20) -> 19829878 | K20: =SUMIF($P$3:$CN$3,K$4,$P20:$CN20) -> 0 | L20: =SUMIF($P$3:$CN$3,L$4,$P20:$CN20) -> 0 | M20: =SUMIF($P$3:$CN$3,M$4,$P20:$CN20) -> 0 | N20: =SUMIF($P$3:$CN$3,N$4,$P20:$CN20) -> 0 | AB20: =費用予算!F30 -> 0 | AC20: =費用予算!G30 -> 0 | AD20: =費用予算!H30 -> 0 | AE20: =費用予算!I30 -> 0 | AF20: =費用予算!J30 -> 2252.25 | AG20: =費用予算!K30 -> 13400.888 | AH20: =費用予算!L30 -> 23992.093 | AI20: =費用予算!M30 -> 34053.738 | ... CI20: =費用予算!BM30 -> 741526.67
J21: =SUMIF($P$3:$CN$3,J$4,$P21:$CN21) -> 0 | K21: =SUMIF($P$3:$CN$3,K$4,$P21:$CN21) -> 0 | L21: =SUMIF($P$3:$CN$3,L$4,$P21:$CN21) -> 0 | M21: =SUMIF($P$3:$CN$3,M$4,$P21:$CN21) -> 0 | N21: =SUMIF($P$3:$CN$3,N$4,$P21:$CN21) -> 0
B22: KPI | C22: 原価率 | D22: % | E22: =E14/E5*100 -> 8.4428413 | F22: =F14/F5*100 -> 7.4390754 | G22: =G14/G5*100 -> 7.4461503 | H22: =H14/H5*100 -> 7.5827268 | I22: =I14/I5*100 -> 7.7901052 | J22: =IFERROR(J14/J5*100,"-") -> 7.6484758 | K22: =IFERROR(K14/K5,"-") -> - | L22: =IFERROR(L14/L5,"-") -> - | M22: =IFERROR(M14/M5,"-") -> - | N22: =IFERROR(N14/N5,"-") -> - | AB22: =IFERROR(AB14/AB5*100,"-") -> - | AC22: =AC14/AC5*100 -> 94.249168 | AD22: =AD14/AD5*100 -> 21.100351 | AE22: =AE14/AE5*100 -> 14.339962 | AF22: =AF14/AF5*100 -> 12.152417 | AG22: =AG14/AG5*100 -> 11.506956 | AH22: =AH14/AH5*100 -> 9.0799719 | AI22: =AI14/AI5*100 -> 7.896381 | AJ22: =AJ14/AJ5*100 -> 7.2323206 | ... CI22: =CI14/CI5*100 -> 7.533825
A23: 売上総利益 | D23: 円 | E23: =E5-E14 -> 21150429 | F23: =F5-F14 -> 99594004 | G23: =G5-G14 -> 2.0175351e+08 | H23: =H5-H14 -> 3.207445e+08 | I23: =I5-I14 -> 4.6293012e+08 | J23: =J5-J14 -> 1.1061726e+09 | K23: =K5-K14 -> 0 | L23: =L5-L14 -> 0 | ... N23: =N5-N14 -> 0 | AB23: =AB5-AB14 -> -50000 | AC23: =AC5-AC14 -> 3254.8799 | AD23: =AD5-AD14 -> 261727.01 | AE23: =AE5-AE14 -> 515587.57 | AF23: =AF5-AF14 -> 755815.39 | AG23: =AG5-AG14 -> 1036048 | AH23: =AH5-AH14 -> 1641630.2 | AI23: =AI5-AI14 -> 2242638.4 | ... CI23: =CI5-CI14 -> 44831957
C24: 前期比 | D24: ％ | F24: =IF(E23>0,(F23-E23)/E23,"-") -> 3.7088409 | G24: =IF(F23>0,(G23-F23)/F23,"-") -> 1.0257596 | H24: =IF(G23>0,(H23-G23)/G23,"-") -> 0.58978402 | I24: =IF(H23>0,(I23-H23)/H23,"-") -> 0.4432987 | J24: =IFERROR((I23/E23)^(1/4)-1,"-") -> 1.1629629 | K24: =IF(K23>0,(K23-J23)/J23,"-") -> - | L24: =IF(L23>0,(L23-K23)/K23,"-") -> - | M24: =IF(M23>0,(M23-L23)/L23,"-") -> - | N24: =IF(N23>0,(N23-M23)/M23,"-") -> -
A25: 販管費 | D25: 円 | E25: =SUMIF($AB$3:$CI$3,E$4,$AB25:$CI25) -> 54400000 | F25: =SUMIF($AB$3:$CI$3,F$4,$AB25:$CI25) -> 111500000 | G25: =SUMIF($AB$3:$CI$3,G$4,$AB25:$CI25) -> 205900000 | H25: =SUMIF($AB$3:$CI$3,H$4,$AB25:$CI25) -> 316400000 | I25: =SUMIF($AB$3:$CI$3,I$4,$AB25:$CI25) -> 522100000 | J25: =SUM(E25:I25) -> 1210300000 | K25: =SUMIF($P$3:$CN$3,K$4,$P25:$CN25) -> 0 | L25: =SUMIF($P$3:$CN$3,L$4,$P25:$CN25) -> 0 | M25: =SUMIF($P$3:$CN$3,M$4,$P25:$CN25) -> 0 | N25: =SUMIF($P$3:$CN$3,N$4,$P25:$CN25) -> 0 | AB25: =AB26+AB27+AB31+AB35+AB39+AB43+AB46+AB50+AB51+AB52+AB53+AB54+AB58+AB61+AB62+AB63+AB64+AB65+AB66+AB67+AB68+AB69+AB70+AB71+AB72+AB75+AB78+AB79 -> 4533335 | AC25: =AC26+AC27+AC31+AC35+AC39+AC43+AC46+AC50+AC51+AC52+AC53+AC54+AC58+AC61+AC62+AC63+AC64+AC65+AC66+AC67+AC68+AC69+AC70+AC71+AC72+AC75+AC78+AC79 -> 4533335 | AD25: =AD26+AD27+AD31+AD35+AD39+AD43+AD46+AD50+AD51+AD52+AD53+AD54+AD58+AD61+AD62+AD63+AD64+AD65+AD66+AD67+AD68+AD69+AD70+AD71+AD72+AD75+AD78+AD79 -> 4533335 | AE25: =AE26+AE27+AE31+AE35+AE39+AE43+AE46+AE50+AE51+AE52+AE53+AE54+AE58+AE61+AE62+AE63+AE64+AE65+AE66+AE67+AE68+AE69+AE70+AE71+AE72+AE75+AE78+AE79 -> 4533335 | AF25: =AF26+AF27+AF31+AF35+AF39+AF43+AF46+AF50+AF51+AF52+AF53+AF54+AF58+AF61+AF62+AF63+AF64+AF65+AF66+AF67+AF68+AF69+AF70+AF71+AF72+AF75+AF78+AF79 -> 4533335 | AG25: =AG26+AG27+AG31+AG35+AG39+AG43+AG46+AG50+AG51+AG52+AG53+AG54+AG58+AG61+AG62+AG63+AG64+AG65+AG66+AG67+AG68+AG69+AG70+AG71+AG72+AG75+AG78+AG79 -> 4533335 | AH25: =AH26+AH27+AH31+AH35+AH39+AH43+AH46+AH50+AH51+AH52+AH53+AH54+AH58+AH61+AH62+AH63+AH64+AH65+AH66+AH67+AH68+AH69+AH70+AH71+AH72+AH75+AH78+AH79 -> 4533335 | AI25: =AI26+AI27+AI31+AI35+AI39+AI43+AI46+AI50+AI51+AI52+AI53+AI54+AI58+AI61+AI62+AI63+AI64+AI65+AI66+AI67+AI68+AI69+AI70+AI71+AI72+AI75+AI78+AI79 -> 4533335 | ... CI25: =CI26+CI27+CI31+CI35+CI39+CI43+CI46+CI50+CI51+CI52+CI53+CI54+CI58+CI61+CI62+CI63+CI64+CI65+CI66+CI67+CI68+CI69+CI70+CI71+CI72+CI75+CI78+CI79 -> 43508326
B26: 役員報酬 | E26: =SUMIF($AB$3:$CI$3,E$4,$AB26:$CI26) -> 12000000 | F26: =SUMIF($AB$3:$CI$3,F$4,$AB26:$CI26) -> 15000000 | G26: =SUMIF($AB$3:$CI$3,G$4,$AB26:$CI26) -> 18000000 | H26: =SUMIF($AB$3:$CI$3,H$4,$AB26:$CI26) -> 24000000 | I26: =SUMIF($AB$3:$CI$3,I$4,$AB26:$CI26) -> 30000000 | J26: =SUM(E26:I26) -> 99000000 | K26: =SUMIF($Q$3:$CN$3,K$4,$Q26:$CN26) -> 0 | L26: =SUMIF($Q$3:$CN$3,L$4,$Q26:$CN26) -> 0 | M26: =SUMIF($Q$3:$CN$3,M$4,$Q26:$CN26) -> 0 | N26: =SUMIF($Q$3:$CN$3,N$4,$Q26:$CN26) -> 0 | AB26: =ROUND(INDEX(販管費予算!$E$5:$I$5,MATCH(AB$3,販管費予算!$E$4:$I$4,0))/12,0)+IF(COUNTIF($AB$3:AB$3,AB$3)=12,INDEX(販管費予算!$E$5:$I$5,MATCH(AB$3,販管費予算!$E$4:$I$4,0))-12*ROUND(INDEX(販管費予算!$E$5:$I$5,MATCH(AB$3,販管費予算!$E$4:$I$4,0))/12,0),0) -> 1000000 | AC26: =ROUND(INDEX(販管費予算!$E$5:$I$5,MATCH(AC$3,販管費予算!$E$4:$I$4,0))/12,0)+IF(COUNTIF($AB$3:AC$3,AC$3)=12,INDEX(販管費予算!$E$5:$I$5,MATCH(AC$3,販管費予算!$E$4:$I$4,0))-12*ROUND(INDEX(販管費予算!$E$5:$I$5,MATCH(AC$3,販管費予算!$E$4:$I$4,0))/12,0),0) -> 1000000 | AD26: =ROUND(INDEX(販管費予算!$E$5:$I$5,MATCH(AD$3,販管費予算!$E$4:$I$4,0))/12,0)+IF(COUNTIF($AB$3:AD$3,AD$3)=12,INDEX(販管費予算!$E$5:$I$5,MATCH(AD$3,販管費予算!$E$4:$I$4,0))-12*ROUND(INDEX(販管費予算!$E$5:$I$5,MATCH(AD$3,販管費予算!$E$4:$I$4,0))/12,0),0) -> 1000000 | AE26: =ROUND(INDEX(販管費予算!$E$5:$I$5,MATCH(AE$3,販管費予算!$E$4:$I$4,0))/12,0)+IF(COUNTIF($AB$3:AE$3,AE$3)=12,INDEX(販管費予算!$E$5:$I$5,MATCH(AE$3,販管費予算!$E$4:$I$4,0))-12*ROUND(INDEX(販管費予算!$E$5:$I$5,MATCH(AE$3,販管費予算!$E$4:$I$4,0))/12,0),0) -> 1000000 | AF26: =ROUND(INDEX(販管費予算!$E$5:$I$5,MATCH(AF$3,販管費予算!$E$4:$I$4,0))/12,0)+IF(COUNTIF($AB$3:AF$3,AF$3)=12,INDEX(販管費予算!$E$5:$I$5,MATCH(AF$3,販管費予算!$E$4:$I$4,0))-12*ROUND(INDEX(販管費予算!$E$5:$I$5,MATCH(AF$3,販管費予算!$E$4:$I$4,0))/12,0),0) -> 1000000 | AG26: =ROUND(INDEX(販管費予算!$E$5:$I$5,MATCH(AG$3,販管費予算!$E$4:$I$4,0))/12,0)+IF(COUNTIF($AB$3:AG$3,AG$3)=12,INDEX(販管費予算!$E$5:$I$5,MATCH(AG$3,販管費予算!$E$4:$I$4,0))-12*ROUND(INDEX(販管費予算!$E$5:$I$5,MATCH(AG$3,販管費予算!$E$4:$I$4,0))/12,0),0) -> 1000000 | AH26: =ROUND(INDEX(販管費予算!$E$5:$I$5,MATCH(AH$3,販管費予算!$E$4:$I$4,0))/12,0)+IF(COUNTIF($AB$3:AH$3,AH$3)=12,INDEX(販管費予算!$E$5:$I$5,MATCH(AH$3,販管費予算!$E$4:$I$4,0))-12*ROUND(INDEX(販管費予算!$E$5:$I$5,MATCH(AH$3,販管費予算!$E$4:$I$4,0))/12,0),0) -> 1000000 | AI26: =ROUND(INDEX(販管費予算!$E$5:$I$5,MATCH(AI$3,販管費予算!$E$4:$I$4,0))/12,0)+IF(COUNTIF($AB$3:AI$3,AI$3)=12,INDEX(販管費予算!$E$5:$I$5,MATCH(AI$3,販管費予算!$E$4:$I$4,0))-12*ROUND(INDEX(販管費予算!$E$5:$I$5,MATCH(AI$3,販管費予算!$E$4:$I$4,0))/12,0),0) -> 1000000 | ... CI26: =ROUND(INDEX(販管費予算!$E$5:$I$5,MATCH(CI$3,販管費予算!$E$4:$I$4,0))/12,0)+IF(COUNTIF($AB$3:CI$3,CI$3)=12,INDEX(販管費予算!$E$5:$I$5,MATCH(CI$3,販管費予算!$E$4:$I$4,0))-12*ROUND(INDEX(販管費予算!$E$5:$I$5,MATCH(CI$3,販管費予算!$E$4:$I$4,0))/12,0),0) -> 2500000
B27: 給与手当 | E27: =SUMIF($AB$3:$CI$3,E$4,$AB27:$CI27) -> 12000000 | F27: =SUMIF($AB$3:$CI$3,F$4,$AB27:$CI27) -> 30000000 | G27: =SUMIF($AB$3:$CI$3,G$4,$AB27:$CI27) -> 60000000 | H27: =SUMIF($AB$3:$CI$3,H$4,$AB27:$CI27) -> 90000000 | I27: =SUMIF($AB$3:$CI$3,I$4,$AB27:$CI27) -> 150000000 | J27: =SUM(E27:I27) -> 342000000 | K27: =SUMIF($Q$3:$CN$3,K$4,$Q27:$CN27) -> 0 | L27: =SUMIF($Q$3:$CN$3,L$4,$Q27:$CN27) -> 0 | M27: =SUMIF($Q$3:$CN$3,M$4,$Q27:$CN27) -> 0 | N27: =SUMIF($Q$3:$CN$3,N$4,$Q27:$CN27) -> 0 | AB27: =SUM(AB28:AB30) -> 1000000 | AC27: =SUM(AC28:AC30) -> 1000000 | AD27: =SUM(AD28:AD30) -> 1000000 | AE27: =SUM(AE28:AE30) -> 1000000 | AF27: =SUM(AF28:AF30) -> 1000000 | AG27: =SUM(AG28:AG30) -> 1000000 | AH27: =SUM(AH28:AH30) -> 1000000 | AI27: =SUM(AI28:AI30) -> 1000000 | ... CI27: =SUM(CI28:CI30) -> 12500000
C28: 全社 | E28: =SUMIF($AB$3:$CI$3,E$4,$AB28:$CI28) -> 12000000 | F28: =SUMIF($AB$3:$CI$3,F$4,$AB28:$CI28) -> 30000000 | G28: =SUMIF($AB$3:$CI$3,G$4,$AB28:$CI28) -> 60000000 | H28: =SUMIF($AB$3:$CI$3,H$4,$AB28:$CI28) -> 90000000 | I28: =SUMIF($AB$3:$CI$3,I$4,$AB28:$CI28) -> 150000000 | J28: =SUM(E28:I28) -> 342000000 | K28: =SUMIF($Q$3:$CN$3,K$4,$Q28:$CN28) -> 0 | L28: =SUMIF($Q$3:$CN$3,L$4,$Q28:$CN28) -> 0 | M28: =SUMIF($Q$3:$CN$3,M$4,$Q28:$CN28) -> 0 | N28: =SUMIF($Q$3:$CN$3,N$4,$Q28:$CN28) -> 0 | AB28: =ROUND(INDEX(販管費予算!$E$6:$I$6,MATCH(AB$3,販管費予算!$E$4:$I$4,0))/12,0)+IF(COUNTIF($AB$3:AB$3,AB$3)=12,INDEX(販管費予算!$E$6:$I$6,MATCH(AB$3,販管費予算!$E$4:$I$4,0))-12*ROUND(INDEX(販管費予算!$E$6:$I$6,MATCH(AB$3,販管費予算!$E$4:$I$4,0))/12,0),0) -> 1000000 | AC28: =ROUND(INDEX(販管費予算!$E$6:$I$6,MATCH(AC$3,販管費予算!$E$4:$I$4,0))/12,0)+IF(COUNTIF($AB$3:AC$3,AC$3)=12,INDEX(販管費予算!$E$6:$I$6,MATCH(AC$3,販管費予算!$E$4:$I$4,0))-12*ROUND(INDEX(販管費予算!$E$6:$I$6,MATCH(AC$3,販管費予算!$E$4:$I$4,0))/12,0),0) -> 1000000 | AD28: =ROUND(INDEX(販管費予算!$E$6:$I$6,MATCH(AD$3,販管費予算!$E$4:$I$4,0))/12,0)+IF(COUNTIF($AB$3:AD$3,AD$3)=12,INDEX(販管費予算!$E$6:$I$6,MATCH(AD$3,販管費予算!$E$4:$I$4,0))-12*ROUND(INDEX(販管費予算!$E$6:$I$6,MATCH(AD$3,販管費予算!$E$4:$I$4,0))/12,0),0) -> 1000000 | AE28: =ROUND(INDEX(販管費予算!$E$6:$I$6,MATCH(AE$3,販管費予算!$E$4:$I$4,0))/12,0)+IF(COUNTIF($AB$3:AE$3,AE$3)=12,INDEX(販管費予算!$E$6:$I$6,MATCH(AE$3,販管費予算!$E$4:$I$4,0))-12*ROUND(INDEX(販管費予算!$E$6:$I$6,MATCH(AE$3,販管費予算!$E$4:$I$4,0))/12,0),0) -> 1000000 | AF28: =ROUND(INDEX(販管費予算!$E$6:$I$6,MATCH(AF$3,販管費予算!$E$4:$I$4,0))/12,0)+IF(COUNTIF($AB$3:AF$3,AF$3)=12,INDEX(販管費予算!$E$6:$I$6,MATCH(AF$3,販管費予算!$E$4:$I$4,0))-12*ROUND(INDEX(販管費予算!$E$6:$I$6,MATCH(AF$3,販管費予算!$E$4:$I$4,0))/12,0),0) -> 1000000 | AG28: =ROUND(INDEX(販管費予算!$E$6:$I$6,MATCH(AG$3,販管費予算!$E$4:$I$4,0))/12,0)+IF(COUNTIF($AB$3:AG$3,AG$3)=12,INDEX(販管費予算!$E$6:$I$6,MATCH(AG$3,販管費予算!$E$4:$I$4,0))-12*ROUND(INDEX(販管費予算!$E$6:$I$6,MATCH(AG$3,販管費予算!$E$4:$I$4,0))/12,0),0) -> 1000000 | AH28: =ROUND(INDEX(販管費予算!$E$6:$I$6,MATCH(AH$3,販管費予算!$E$4:$I$4,0))/12,0)+IF(COUNTIF($AB$3:AH$3,AH$3)=12,INDEX(販管費予算!$E$6:$I$6,MATCH(AH$3,販管費予算!$E$4:$I$4,0))-12*ROUND(INDEX(販管費予算!$E$6:$I$6,MATCH(AH$3,販管費予算!$E$4:$I$4,0))/12,0),0) -> 1000000 | AI28: =ROUND(INDEX(販管費予算!$E$6:$I$6,MATCH(AI$3,販管費予算!$E$4:$I$4,0))/12,0)+IF(COUNTIF($AB$3:AI$3,AI$3)=12,INDEX(販管費予算!$E$6:$I$6,MATCH(AI$3,販管費予算!$E$4:$I$4,0))-12*ROUND(INDEX(販管費予算!$E$6:$I$6,MATCH(AI$3,販管費予算!$E$4:$I$4,0))/12,0),0) -> 1000000 | ... CI28: =ROUND(INDEX(販管費予算!$E$6:$I$6,MATCH(CI$3,販管費予算!$E$4:$I$4,0))/12,0)+IF(COUNTIF($AB$3:CI$3,CI$3)=12,INDEX(販管費予算!$E$6:$I$6,MATCH(CI$3,販管費予算!$E$4:$I$4,0))-12*ROUND(INDEX(販管費予算!$E$6:$I$6,MATCH(CI$3,販管費予算!$E$4:$I$4,0))/12,0),0) -> 12500000
C29: SaaS | E29: =SUMIF($AB$3:$CI$3,E$4,$AB29:$CI29) -> 0 | F29: =SUMIF($AB$3:$CI$3,F$4,$AB29:$CI29) -> 0 | G29: =SUMIF($AB$3:$CI$3,G$4,$AB29:$CI29) -> 0 | H29: =SUMIF($AB$3:$CI$3,H$4,$AB29:$CI29) -> 0 | I29: =SUMIF($AB$3:$CI$3,I$4,$AB29:$CI29) -> 0 | J29: =SUM(E29:I29) -> 0 | K29: =SUMIF($Q$3:$CN$3,K$4,$Q29:$CN29) -> 0 | L29: =SUMIF($Q$3:$CN$3,L$4,$Q29:$CN29) -> 0 | M29: =SUMIF($Q$3:$CN$3,M$4,$Q29:$CN29) -> 0 | N29: =SUMIF($Q$3:$CN$3,N$4,$Q29:$CN29) -> 0
C30: 事業・組織再生コンサル | E30: =SUMIF($AB$3:$CI$3,E$4,$AB30:$CI30) -> 0 | F30: =SUMIF($AB$3:$CI$3,F$4,$AB30:$CI30) -> 0 | G30: =SUMIF($AB$3:$CI$3,G$4,$AB30:$CI30) -> 0 | H30: =SUMIF($AB$3:$CI$3,H$4,$AB30:$CI30) -> 0 | I30: =SUMIF($AB$3:$CI$3,I$4,$AB30:$CI30) -> 0 | J30: =SUM(E30:I30) -> 0 | K30: =SUMIF($Q$3:$CN$3,K$4,$Q30:$CN30) -> 0 | L30: =SUMIF($Q$3:$CN$3,L$4,$Q30:$CN30) -> 0 | M30: =SUMIF($Q$3:$CN$3,M$4,$Q30:$CN30) -> 0 | N30: =SUMIF($Q$3:$CN$3,N$4,$Q30:$CN30) -> 0
B31: 賞与手当 | E31: =SUMIF($AB$3:$CI$3,E$4,$AB31:$CI31) -> 0 | F31: =SUMIF($AB$3:$CI$3,F$4,$AB31:$CI31) -> 3000000 | G31: =SUMIF($AB$3:$CI$3,G$4,$AB31:$CI31) -> 6000000 | H31: =SUMIF($AB$3:$CI$3,H$4,$AB31:$CI31) -> 9000000 | I31: =SUMIF($AB$3:$CI$3,I$4,$AB31:$CI31) -> 15000000 | J31: =SUM(E31:I31) -> 33000000 | K31: =SUMIF($Q$3:$CN$3,K$4,$Q31:$CN31) -> 0 | L31: =SUMIF($Q$3:$CN$3,L$4,$Q31:$CN31) -> 0 | M31: =SUMIF($Q$3:$CN$3,M$4,$Q31:$CN31) -> 0 | N31: =SUMIF($Q$3:$CN$3,N$4,$Q31:$CN31) -> 0 | AB31: =SUM(AB32:AB34) -> 0 | AC31: =SUM(AC32:AC34) -> 0 | AD31: =SUM(AD32:AD34) -> 0 | AE31: =SUM(AE32:AE34) -> 0 | AF31: =SUM(AF32:AF34) -> 0 | AG31: =SUM(AG32:AG34) -> 0 | AH31: =SUM(AH32:AH34) -> 0 | AI31: =SUM(AI32:AI34) -> 0 | ... CI31: =SUM(CI32:CI34) -> 1250000
C32: 全社 | E32: =SUMIF($AB$3:$CI$3,E$4,$AB32:$CI32) -> 0 | F32: =SUMIF($AB$3:$CI$3,F$4,$AB32:$CI32) -> 3000000 | G32: =SUMIF($AB$3:$CI$3,G$4,$AB32:$CI32) -> 6000000 | H32: =SUMIF($AB$3:$CI$3,H$4,$AB32:$CI32) -> 9000000 | I32: =SUMIF($AB$3:$CI$3,I$4,$AB32:$CI32) -> 15000000 | J32: =SUM(E32:I32) -> 33000000 | K32: =SUMIF($Q$3:$CN$3,K$4,$Q32:$CN32) -> 0 | L32: =SUMIF($Q$3:$CN$3,L$4,$Q32:$CN32) -> 0 | M32: =SUMIF($Q$3:$CN$3,M$4,$Q32:$CN32) -> 0 | N32: =SUMIF($Q$3:$CN$3,N$4,$Q32:$CN32) -> 0 | AB32: =ROUND(INDEX(販管費予算!$E$7:$I$7,MATCH(AB$3,販管費予算!$E$4:$I$4,0))/12,0)+IF(COUNTIF($AB$3:AB$3,AB$3)=12,INDEX(販管費予算!$E$7:$I$7,MATCH(AB$3,販管費予算!$E$4:$I$4,0))-12*ROUND(INDEX(販管費予算!$E$7:$I$7,MATCH(AB$3,販管費予算!$E$4:$I$4,0))/12,0),0) -> 0 | AC32: =ROUND(INDEX(販管費予算!$E$7:$I$7,MATCH(AC$3,販管費予算!$E$4:$I$4,0))/12,0)+IF(COUNTIF($AB$3:AC$3,AC$3)=12,INDEX(販管費予算!$E$7:$I$7,MATCH(AC$3,販管費予算!$E$4:$I$4,0))-12*ROUND(INDEX(販管費予算!$E$7:$I$7,MATCH(AC$3,販管費予算!$E$4:$I$4,0))/12,0),0) -> 0 | AD32: =ROUND(INDEX(販管費予算!$E$7:$I$7,MATCH(AD$3,販管費予算!$E$4:$I$4,0))/12,0)+IF(COUNTIF($AB$3:AD$3,AD$3)=12,INDEX(販管費予算!$E$7:$I$7,MATCH(AD$3,販管費予算!$E$4:$I$4,0))-12*ROUND(INDEX(販管費予算!$E$7:$I$7,MATCH(AD$3,販管費予算!$E$4:$I$4,0))/12,0),0) -> 0 | AE32: =ROUND(INDEX(販管費予算!$E$7:$I$7,MATCH(AE$3,販管費予算!$E$4:$I$4,0))/12,0)+IF(COUNTIF($AB$3:AE$3,AE$3)=12,INDEX(販管費予算!$E$7:$I$7,MATCH(AE$3,販管費予算!$E$4:$I$4,0))-12*ROUND(INDEX(販管費予算!$E$7:$I$7,MATCH(AE$3,販管費予算!$E$4:$I$4,0))/12,0),0) -> 0 | AF32: =ROUND(INDEX(販管費予算!$E$7:$I$7,MATCH(AF$3,販管費予算!$E$4:$I$4,0))/12,0)+IF(COUNTIF($AB$3:AF$3,AF$3)=12,INDEX(販管費予算!$E$7:$I$7,MATCH(AF$3,販管費予算!$E$4:$I$4,0))-12*ROUND(INDEX(販管費予算!$E$7:$I$7,MATCH(AF$3,販管費予算!$E$4:$I$4,0))/12,0),0) -> 0 | AG32: =ROUND(INDEX(販管費予算!$E$7:$I$7,MATCH(AG$3,販管費予算!$E$4:$I$4,0))/12,0)+IF(COUNTIF($AB$3:AG$3,AG$3)=12,INDEX(販管費予算!$E$7:$I$7,MATCH(AG$3,販管費予算!$E$4:$I$4,0))-12*ROUND(INDEX(販管費予算!$E$7:$I$7,MATCH(AG$3,販管費予算!$E$4:$I$4,0))/12,0),0) -> 0 | AH32: =ROUND(INDEX(販管費予算!$E$7:$I$7,MATCH(AH$3,販管費予算!$E$4:$I$4,0))/12,0)+IF(COUNTIF($AB$3:AH$3,AH$3)=12,INDEX(販管費予算!$E$7:$I$7,MATCH(AH$3,販管費予算!$E$4:$I$4,0))-12*ROUND(INDEX(販管費予算!$E$7:$I$7,MATCH(AH$3,販管費予算!$E$4:$I$4,0))/12,0),0) -> 0 | AI32: =ROUND(INDEX(販管費予算!$E$7:$I$7,MATCH(AI$3,販管費予算!$E$4:$I$4,0))/12,0)+IF(COUNTIF($AB$3:AI$3,AI$3)=12,INDEX(販管費予算!$E$7:$I$7,MATCH(AI$3,販管費予算!$E$4:$I$4,0))-12*ROUND(INDEX(販管費予算!$E$7:$I$7,MATCH(AI$3,販管費予算!$E$4:$I$4,0))/12,0),0) -> 0 | ... CI32: =ROUND(INDEX(販管費予算!$E$7:$I$7,MATCH(CI$3,販管費予算!$E$4:$I$4,0))/12,0)+IF(COUNTIF($AB$3:CI$3,CI$3)=12,INDEX(販管費予算!$E$7:$I$7,MATCH(CI$3,販管費予算!$E$4:$I$4,0))-12*ROUND(INDEX(販管費予算!$E$7:$I$7,MATCH(CI$3,販管費予算!$E$4:$I$4,0))/12,0),0) -> 1250000
C33: SaaS | E33: =SUMIF($AB$3:$CI$3,E$4,$AB33:$CI33) -> 0 | F33: =SUMIF($AB$3:$CI$3,F$4,$AB33:$CI33) -> 0 | G33: =SUMIF($AB$3:$CI$3,G$4,$AB33:$CI33) -> 0 | H33: =SUMIF($AB$3:$CI$3,H$4,$AB33:$CI33) -> 0 | I33: =SUMIF($AB$3:$CI$3,I$4,$AB33:$CI33) -> 0 | J33: =SUM(E33:I33) -> 0 | K33: =SUMIF($Q$3:$CN$3,K$4,$Q33:$CN33) -> 0 | L33: =SUMIF($Q$3:$CN$3,L$4,$Q33:$CN33) -> 0 | M33: =SUMIF($Q$3:$CN$3,M$4,$Q33:$CN33) -> 0 | N33: =SUMIF($Q$3:$CN$3,N$4,$Q33:$CN33) -> 0
C34: 事業・組織再生コンサル | E34: =SUMIF($AB$3:$CI$3,E$4,$AB34:$CI34) -> 0 | F34: =SUMIF($AB$3:$CI$3,F$4,$AB34:$CI34) -> 0 | G34: =SUMIF($AB$3:$CI$3,G$4,$AB34:$CI34) -> 0 | H34: =SUMIF($AB$3:$CI$3,H$4,$AB34:$CI34) -> 0 | I34: =SUMIF($AB$3:$CI$3,I$4,$AB34:$CI34) -> 0 | J34: =SUM(E34:I34) -> 0 | K34: =SUMIF($Q$3:$CN$3,K$4,$Q34:$CN34) -> 0 | L34: =SUMIF($Q$3:$CN$3,L$4,$Q34:$CN34) -> 0 | M34: =SUMIF($Q$3:$CN$3,M$4,$Q34:$CN34) -> 0 | N34: =SUMIF($Q$3:$CN$3,N$4,$Q34:$CN34) -> 0
B35: 法定福利費 | E35: =SUMIF($AB$3:$CI$3,E$4,$AB35:$CI35) -> 3600000 | F35: =SUMIF($AB$3:$CI$3,F$4,$AB35:$CI35) -> 7200000 | G35: =SUMIF($AB$3:$CI$3,G$4,$AB35:$CI35) -> 14400000 | H35: =SUMIF($AB$3:$CI$3,H$4,$AB35:$CI35) -> 22000000 | I35: =SUMIF($AB$3:$CI$3,I$4,$AB35:$CI35) -> 38000000 | J35: =SUM(E35:I35) -> 85200000 | K35: =SUMIF($Q$3:$CN$3,K$4,$Q35:$CN35) -> 0 | L35: =SUMIF($Q$3:$CN$3,L$4,$Q35:$CN35) -> 0 | M35: =SUMIF($Q$3:$CN$3,M$4,$Q35:$CN35) -> 0 | N35: =SUMIF($Q$3:$CN$3,N$4,$Q35:$CN35) -> 0 | AB35: =SUM(AB36:AB38) -> 300000 | AC35: =SUM(AC36:AC38) -> 300000 | AD35: =SUM(AD36:AD38) -> 300000 | AE35: =SUM(AE36:AE38) -> 300000 | AF35: =SUM(AF36:AF38) -> 300000 | AG35: =SUM(AG36:AG38) -> 300000 | AH35: =SUM(AH36:AH38) -> 300000 | AI35: =SUM(AI36:AI38) -> 300000 | ... CI35: =SUM(CI36:CI38) -> 3166663
C36: 全社 | E36: =SUMIF($AB$3:$CI$3,E$4,$AB36:$CI36) -> 3600000 | F36: =SUMIF($AB$3:$CI$3,F$4,$AB36:$CI36) -> 7200000 | G36: =SUMIF($AB$3:$CI$3,G$4,$AB36:$CI36) -> 14400000 | H36: =SUMIF($AB$3:$CI$3,H$4,$AB36:$CI36) -> 22000000 | I36: =SUMIF($AB$3:$CI$3,I$4,$AB36:$CI36) -> 38000000 | J36: =SUM(E36:I36) -> 85200000 | K36: =SUMIF($Q$3:$CN$3,K$4,$Q36:$CN36) -> 0 | L36: =SUMIF($Q$3:$CN$3,L$4,$Q36:$CN36) -> 0 | M36: =SUMIF($Q$3:$CN$3,M$4,$Q36:$CN36) -> 0 | N36: =SUMIF($Q$3:$CN$3,N$4,$Q36:$CN36) -> 0 | AB36: =ROUND(INDEX(販管費予算!$E$8:$I$8,MATCH(AB$3,販管費予算!$E$4:$I$4,0))/12,0)+IF(COUNTIF($AB$3:AB$3,AB$3)=12,INDEX(販管費予算!$E$8:$I$8,MATCH(AB$3,販管費予算!$E$4:$I$4,0))-12*ROUND(INDEX(販管費予算!$E$8:$I$8,MATCH(AB$3,販管費予算!$E$4:$I$4,0))/12,0),0) -> 300000 | AC36: =ROUND(INDEX(販管費予算!$E$8:$I$8,MATCH(AC$3,販管費予算!$E$4:$I$4,0))/12,0)+IF(COUNTIF($AB$3:AC$3,AC$3)=12,INDEX(販管費予算!$E$8:$I$8,MATCH(AC$3,販管費予算!$E$4:$I$4,0))-12*ROUND(INDEX(販管費予算!$E$8:$I$8,MATCH(AC$3,販管費予算!$E$4:$I$4,0))/12,0),0) -> 300000 | AD36: =ROUND(INDEX(販管費予算!$E$8:$I$8,MATCH(AD$3,販管費予算!$E$4:$I$4,0))/12,0)+IF(COUNTIF($AB$3:AD$3,AD$3)=12,INDEX(販管費予算!$E$8:$I$8,MATCH(AD$3,販管費予算!$E$4:$I$4,0))-12*ROUND(INDEX(販管費予算!$E$8:$I$8,MATCH(AD$3,販管費予算!$E$4:$I$4,0))/12,0),0) -> 300000 | AE36: =ROUND(INDEX(販管費予算!$E$8:$I$8,MATCH(AE$3,販管費予算!$E$4:$I$4,0))/12,0)+IF(COUNTIF($AB$3:AE$3,AE$3)=12,INDEX(販管費予算!$E$8:$I$8,MATCH(AE$3,販管費予算!$E$4:$I$4,0))-12*ROUND(INDEX(販管費予算!$E$8:$I$8,MATCH(AE$3,販管費予算!$E$4:$I$4,0))/12,0),0) -> 300000 | AF36: =ROUND(INDEX(販管費予算!$E$8:$I$8,MATCH(AF$3,販管費予算!$E$4:$I$4,0))/12,0)+IF(COUNTIF($AB$3:AF$3,AF$3)=12,INDEX(販管費予算!$E$8:$I$8,MATCH(AF$3,販管費予算!$E$4:$I$4,0))-12*ROUND(INDEX(販管費予算!$E$8:$I$8,MATCH(AF$3,販管費予算!$E$4:$I$4,0))/12,0),0) -> 300000 | AG36: =ROUND(INDEX(販管費予算!$E$8:$I$8,MATCH(AG$3,販管費予算!$E$4:$I$4,0))/12,0)+IF(COUNTIF($AB$3:AG$3,AG$3)=12,INDEX(販管費予算!$E$8:$I$8,MATCH(AG$3,販管費予算!$E$4:$I$4,0))-12*ROUND(INDEX(販管費予算!$E$8:$I$8,MATCH(AG$3,販管費予算!$E$4:$I$4,0))/12,0),0) -> 300000 | AH36: =ROUND(INDEX(販管費予算!$E$8:$I$8,MATCH(AH$3,販管費予算!$E$4:$I$4,0))/12,0)+IF(COUNTIF($AB$3:AH$3,AH$3)=12,INDEX(販管費予算!$E$8:$I$8,MATCH(AH$3,販管費予算!$E$4:$I$4,0))-12*ROUND(INDEX(販管費予算!$E$8:$I$8,MATCH(AH$3,販管費予算!$E$4:$I$4,0))/12,0),0) -> 300000 | AI36: =ROUND(INDEX(販管費予算!$E$8:$I$8,MATCH(AI$3,販管費予算!$E$4:$I$4,0))/12,0)+IF(COUNTIF($AB$3:AI$3,AI$3)=12,INDEX(販管費予算!$E$8:$I$8,MATCH(AI$3,販管費予算!$E$4:$I$4,0))-12*ROUND(INDEX(販管費予算!$E$8:$I$8,MATCH(AI$3,販管費予算!$E$4:$I$4,0))/12,0),0) -> 300000 | ... CI36: =ROUND(INDEX(販管費予算!$E$8:$I$8,MATCH(CI$3,販管費予算!$E$4:$I$4,0))/12,0)+IF(COUNTIF($AB$3:CI$3,CI$3)=12,INDEX(販管費予算!$E$8:$I$8,MATCH(CI$3,販管費予算!$E$4:$I$4,0))-12*ROUND(INDEX(販管費予算!$E$8:$I$8,MATCH(CI$3,販管費予算!$E$4:$I$4,0))/12,0),0) -> 3166663
C37: SaaS | E37: =SUMIF($AB$3:$CI$3,E$4,$AB37:$CI37) -> 0 | F37: =SUMIF($AB$3:$CI$3,F$4,$AB37:$CI37) -> 0 | G37: =SUMIF($AB$3:$CI$3,G$4,$AB37:$CI37) -> 0 | H37: =SUMIF($AB$3:$CI$3,H$4,$AB37:$CI37) -> 0 | I37: =SUMIF($AB$3:$CI$3,I$4,$AB37:$CI37) -> 0 | J37: =SUM(E37:I37) -> 0 | K37: =SUMIF($Q$3:$CN$3,K$4,$Q37:$CN37) -> 0 | L37: =SUMIF($Q$3:$CN$3,L$4,$Q37:$CN37) -> 0 | M37: =SUMIF($Q$3:$CN$3,M$4,$Q37:$CN37) -> 0 | N37: =SUMIF($Q$3:$CN$3,N$4,$Q37:$CN37) -> 0
C38: 事業・組織再生コンサル | E38: =SUMIF($AB$3:$CI$3,E$4,$AB38:$CI38) -> 0 | F38: =SUMIF($AB$3:$CI$3,F$4,$AB38:$CI38) -> 0 | G38: =SUMIF($AB$3:$CI$3,G$4,$AB38:$CI38) -> 0 | H38: =SUMIF($AB$3:$CI$3,H$4,$AB38:$CI38) -> 0 | I38: =SUMIF($AB$3:$CI$3,I$4,$AB38:$CI38) -> 0 | J38: =SUM(E38:I38) -> 0 | K38: =SUMIF($Q$3:$CN$3,K$4,$Q38:$CN38) -> 0 | L38: =SUMIF($Q$3:$CN$3,L$4,$Q38:$CN38) -> 0 | M38: =SUMIF($Q$3:$CN$3,M$4,$Q38:$CN38) -> 0 | N38: =SUMIF($Q$3:$CN$3,N$4,$Q38:$CN38) -> 0
B39: 福利厚生費 | E39: =SUMIF($AB$3:$CI$3,E$4,$AB39:$CI39) -> 300000 | F39: =SUMIF($AB$3:$CI$3,F$4,$AB39:$CI39) -> 600000 | G39: =SUMIF($AB$3:$CI$3,G$4,$AB39:$CI39) -> 1200000 | H39: =SUMIF($AB$3:$CI$3,H$4,$AB39:$CI39) -> 2000000 | I39: =SUMIF($AB$3:$CI$3,I$4,$AB39:$CI39) -> 3500000 | J39: =SUM(E39:I39) -> 7600000 | K39: =SUMIF($Q$3:$CN$3,K$4,$Q39:$CN39) -> 0 | L39: =SUMIF($Q$3:$CN$3,L$4,$Q39:$CN39) -> 0 | M39: =SUMIF($Q$3:$CN$3,M$4,$Q39:$CN39) -> 0 | N39: =SUMIF($Q$3:$CN$3,N$4,$Q39:$CN39) -> 0 | AB39: =SUM(AB40:AB42) -> 25000 | AC39: =SUM(AC40:AC42) -> 25000 | AD39: =SUM(AD40:AD42) -> 25000 | AE39: =SUM(AE40:AE42) -> 25000 | AF39: =SUM(AF40:AF42) -> 25000 | AG39: =SUM(AG40:AG42) -> 25000 | AH39: =SUM(AH40:AH42) -> 25000 | AI39: =SUM(AI40:AI42) -> 25000 | ... CI39: =SUM(CI40:CI42) -> 291663
C40: 全社 | E40: =SUMIF($AB$3:$CI$3,E$4,$AB40:$CI40) -> 300000 | F40: =SUMIF($AB$3:$CI$3,F$4,$AB40:$CI40) -> 600000 | G40: =SUMIF($AB$3:$CI$3,G$4,$AB40:$CI40) -> 1200000 | H40: =SUMIF($AB$3:$CI$3,H$4,$AB40:$CI40) -> 2000000 | I40: =SUMIF($AB$3:$CI$3,I$4,$AB40:$CI40) -> 3500000 | J40: =SUM(E40:I40) -> 7600000 | K40: =SUMIF($Q$3:$CN$3,K$4,$Q40:$CN40) -> 0 | L40: =SUMIF($Q$3:$CN$3,L$4,$Q40:$CN40) -> 0 | M40: =SUMIF($Q$3:$CN$3,M$4,$Q40:$CN40) -> 0 | N40: =SUMIF($Q$3:$CN$3,N$4,$Q40:$CN40) -> 0 | AB40: =ROUND(INDEX(販管費予算!$E$9:$I$9,MATCH(AB$3,販管費予算!$E$4:$I$4,0))/12,0)+IF(COUNTIF($AB$3:AB$3,AB$3)=12,INDEX(販管費予算!$E$9:$I$9,MATCH(AB$3,販管費予算!$E$4:$I$4,0))-12*ROUND(INDEX(販管費予算!$E$9:$I$9,MATCH(AB$3,販管費予算!$E$4:$I$4,0))/12,0),0) -> 25000 | AC40: =ROUND(INDEX(販管費予算!$E$9:$I$9,MATCH(AC$3,販管費予算!$E$4:$I$4,0))/12,0)+IF(COUNTIF($AB$3:AC$3,AC$3)=12,INDEX(販管費予算!$E$9:$I$9,MATCH(AC$3,販管費予算!$E$4:$I$4,0))-12*ROUND(INDEX(販管費予算!$E$9:$I$9,MATCH(AC$3,販管費予算!$E$4:$I$4,0))/12,0),0) -> 25000 | AD40: =ROUND(INDEX(販管費予算!$E$9:$I$9,MATCH(AD$3,販管費予算!$E$4:$I$4,0))/12,0)+IF(COUNTIF($AB$3:AD$3,AD$3)=12,INDEX(販管費予算!$E$9:$I$9,MATCH(AD$3,販管費予算!$E$4:$I$4,0))-12*ROUND(INDEX(販管費予算!$E$9:$I$9,MATCH(AD$3,販管費予算!$E$4:$I$4,0))/12,0),0) -> 25000 | AE40: =ROUND(INDEX(販管費予算!$E$9:$I$9,MATCH(AE$3,販管費予算!$E$4:$I$4,0))/12,0)+IF(COUNTIF($AB$3:AE$3,AE$3)=12,INDEX(販管費予算!$E$9:$I$9,MATCH(AE$3,販管費予算!$E$4:$I$4,0))-12*ROUND(INDEX(販管費予算!$E$9:$I$9,MATCH(AE$3,販管費予算!$E$4:$I$4,0))/12,0),0) -> 25000 | AF40: =ROUND(INDEX(販管費予算!$E$9:$I$9,MATCH(AF$3,販管費予算!$E$4:$I$4,0))/12,0)+IF(COUNTIF($AB$3:AF$3,AF$3)=12,INDEX(販管費予算!$E$9:$I$9,MATCH(AF$3,販管費予算!$E$4:$I$4,0))-12*ROUND(INDEX(販管費予算!$E$9:$I$9,MATCH(AF$3,販管費予算!$E$4:$I$4,0))/12,0),0) -> 25000 | AG40: =ROUND(INDEX(販管費予算!$E$9:$I$9,MATCH(AG$3,販管費予算!$E$4:$I$4,0))/12,0)+IF(COUNTIF($AB$3:AG$3,AG$3)=12,INDEX(販管費予算!$E$9:$I$9,MATCH(AG$3,販管費予算!$E$4:$I$4,0))-12*ROUND(INDEX(販管費予算!$E$9:$I$9,MATCH(AG$3,販管費予算!$E$4:$I$4,0))/12,0),0) -> 25000 | AH40: =ROUND(INDEX(販管費予算!$E$9:$I$9,MATCH(AH$3,販管費予算!$E$4:$I$4,0))/12,0)+IF(COUNTIF($AB$3:AH$3,AH$3)=12,INDEX(販管費予算!$E$9:$I$9,MATCH(AH$3,販管費予算!$E$4:$I$4,0))-12*ROUND(INDEX(販管費予算!$E$9:$I$9,MATCH(AH$3,販管費予算!$E$4:$I$4,0))/12,0),0) -> 25000 | AI40: =ROUND(INDEX(販管費予算!$E$9:$I$9,MATCH(AI$3,販管費予算!$E$4:$I$4,0))/12,0)+IF(COUNTIF($AB$3:AI$3,AI$3)=12,INDEX(販管費予算!$E$9:$I$9,MATCH(AI$3,販管費予算!$E$4:$I$4,0))-12*ROUND(INDEX(販管費予算!$E$9:$I$9,MATCH(AI$3,販管費予算!$E$4:$I$4,0))/12,0),0) -> 25000 | ... CI40: =ROUND(INDEX(販管費予算!$E$9:$I$9,MATCH(CI$3,販管費予算!$E$4:$I$4,0))/12,0)+IF(COUNTIF($AB$3:CI$3,CI$3)=12,INDEX(販管費予算!$E$9:$I$9,MATCH(CI$3,販管費予算!$E$4:$I$4,0))-12*ROUND(INDEX(販管費予算!$E$9:$I$9,MATCH(CI$3,販管費予算!$E$4:$I$4,0))/12,0),0) -> 291663
...

Sheet SaaS
C4: 指標 | D4: メモ | F4: M1 | G4: M2 | H4: M3 | I4: M4 | J4: M5 | K4: M6 | L4: M7 | M4: M8 | N4: M9 | O4: M10 | P4: M11 | Q4: M12 | R4: M13 | S4: M1４ | T4: M15 | U4: M16 | V4: M17 | W4: M18 | X4: M19 | Y4: M20 | Z4: M21 | AA4: M22 | AB4: M23 | AC4: M24 | AD4: M25 | AE4: M26 | AF4: M27 | AG4: M28 | AH4: M29 | AI4: M30 | AJ4: M31 | AK4: M32 | AL4: M33 | AM4: M34 | AN4: M35 | AO4: M36 | AP4: M37 | AQ4: M38 | AR4: M39 | AS4: M40 | AT4: M41 | AU4: M42 | AV4: M43 | AW4: M44 | AX4: M45 | AY4: M46 | AZ4: M47 | BA4: M48 | BB4: M49 | BC4: M50 | BD4: M51 | BE4: M52 | BF4: M53 | BG4: M54 | BH4: M55 | BI4: M56 | BJ4: M57 | BK4: M58 | BL4: M59 | BM4: M60 | BN4: Y0 | BO4: Y2 | BP4: Y3 | BQ4: Y4 | BR4: Y5
C5: SAAS売上 | F5: =F6+F10 -> 0 | G5: =G6+G10 -> 42876.146 | H5: =H6+H10 -> 256399.35 | I5: =I6+I10 -> 465652.1 | J5: =J6+J10 -> 670719.79 | K5: =K6+K10 -> 914562.27 | L5: =L6+L10 -> 1153527.9 | M5: =M6+M10 -> 1387714.2 | ... BM5: =BM6+BM10 -> 27073469 | BN5: =SUM(F5:Q5) -> 13155039 | BO5: =SUM(R5:AC5) -> 54970475 | BP5: =SUM(AD5:AO5) -> 1.1300102e+08 | BQ5: =SUM(AP5:BA5) -> 1.8562995e+08 | BR5: =SUM(BB5:BM5) -> 2.7676127e+08
C6: プレミアムプラン売上 | F6: =F7*F8 -> 0 | G6: =G7*G8 -> 7200 | H6: =H7*H8 -> 43056 | I6: =I7*I8 -> 78194.88 | J6: =J7*J8 -> 112630.98 | K6: =K7*K8 -> 153578.36 | L6: =L7*L8 -> 193706.8 | M6: =M7*M8 -> 233032.66 | ... BM6: =BM7*BM8 -> 4546326.9 | BN6: =SUM(F6:Q6) -> 2209067 | BO6: =SUM(R6:AC6) -> 9230946.6 | BP6: =SUM(AD6:AO6) -> 18975758 | BQ6: =SUM(AP6:BA6) -> 31172009 | BR6: =SUM(BB6:BM6) -> 46475286
C7: プレミアムプラン追加費用 | F7: 30000 | G7: 30000 | H7: 30000 | I7: 30000 | J7: 30000 | K7: 30000 | L7: 30000 | M7: 30000 | N7: 30000 | O7: 30000 | P7: 30000 | Q7: 30000 | R7: 30000 | S7: 30000 | T7: 30000 | U7: 30000 | V7: 30000 | W7: 30000 | X7: 30000 | Y7: 30000 | Z7: 30000 | AA7: 30000 | AB7: 30000 | AC7: 30000 | AD7: 30000 | AE7: 30000 | AF7: 30000 | AG7: 30000 | AH7: 30000 | AI7: 30000 | AJ7: 30000 | AK7: 30000 | AL7: 30000 | AM7: 30000 | AN7: 30000 | AO7: 30000 | AP7: 30000 | AQ7: 30000 | AR7: 30000 | AS7: 30000 | AT7: 30000 | AU7: 30000 | AV7: 30000 | AW7: 30000 | AX7: 30000 | AY7: 30000 | AZ7: 30000 | BA7: 30000 | BB7: 30000 | BC7: 30000 | BD7: 30000 | BE7: 30000 | BF7: 30000 | BG7: 30000 | BH7: 30000 | BI7: 30000 | BJ7: 30000 | BK7: 30000 | BL7: 30000 | BM7: 30000 | BN7: 30000 | BO7: 30000 | BP7: 30000 | BQ7: 30000 | BR7: 30000
C8: プレミアムプラン加入数 | F8: =F9*F17 -> 0 | G8: =G9*G17 -> 0.24 | H8: =H9*H17 -> 1.4352 | I8: =I9*I17 -> 2.606496 | J8: =J9*J17 -> 3.7543661 | K8: =K9*K17 -> 5.1192788 | L8: =L9*L17 -> 6.4568932 | M8: =M9*M17 -> 7.7677553 | ... BR8: =BR9*BR17 -> 151.54423
C9: プレミアムプラン加入率 | D9: 税理士ドットコム実働率24% | F9: 0.24 | G9: 0.24 | H9: 0.24 | I9: 0.24 | J9: 0.24 | K9: 0.24 | L9: 0.24 | M9: 0.24 | N9: 0.24 | O9: 0.24 | P9: 0.24 | Q9: 0.24 | R9: 0.24 | S9: 0.24 | T9: 0.24 | U9: 0.24 | V9: 0.24 | W9: 0.24 | X9: 0.24 | Y9: 0.24 | Z9: 0.24 | AA9: 0.24 | AB9: 0.24 | AC9: 0.24 | AD9: 0.24 | AE9: 0.24 | AF9: 0.24 | AG9: 0.24 | AH9: 0.24 | AI9: 0.24 | AJ9: 0.24 | AK9: 0.24 | AL9: 0.24 | AM9: 0.24 | AN9: 0.24 | AO9: 0.24 | AP9: 0.24 | AQ9: 0.24 | AR9: 0.24 | AS9: 0.24 | AT9: 0.24 | AU9: 0.24 | AV9: 0.24 | AW9: 0.24 | AX9: 0.24 | AY9: 0.24 | AZ9: 0.24 | BA9: 0.24 | BB9: 0.24 | BC9: 0.24 | BD9: 0.24 | BE9: 0.24 | BF9: 0.24 | BG9: 0.24 | BH9: 0.24 | BI9: 0.24 | BJ9: 0.24 | BK9: 0.24 | BL9: 0.24 | BM9: 0.24 | BN9: 0.24 | BO9: 0.24 | BP9: 0.24 | BQ9: 0.24 | BR9: 0.24
C10: 通常プラン売上 | F10: =F11*F12 -> 0 | G10: =G11*G12 -> 35676.146 | H10: =H11*H12 -> 213343.35 | I10: =I11*I12 -> 387457.22 | J10: =J11*J12 -> 558088.8 | K10: =K11*K12 -> 760983.9 | L10: =L11*L12 -> 959821.1 | M10: =M11*M12 -> 1154681.6 | ... BM10: =BM11*BM12 -> 22527142 | BN10: =SUM(F10:Q10) -> 10945972 | BO10: =SUM(R10:AC10) -> 45739528 | BP10: =SUM(AD10:AO10) -> 94025265 | BQ10: =SUM(AP10:BA10) -> 1.5445794e+08 | BR10: =SUM(BB10:BM10) -> 2.3028599e+08
C11: システム利用料アカウント単価 | F11: 19800 | G11: 19800 | H11: 19800 | I11: 19800 | J11: 19800 | K11: 19800 | L11: 19800 | M11: 19800 | N11: 19800 | O11: 19800 | P11: 19800 | Q11: 19800 | R11: 19800 | S11: 19800 | T11: 19800 | U11: 19800 | V11: 19800 | W11: 19800 | X11: 19800 | Y11: 19800 | Z11: 19800 | AA11: 19800 | AB11: 19800 | AC11: 19800 | AD11: 19800 | AE11: 19800 | AF11: 19800 | AG11: 19800 | AH11: 19800 | AI11: 19800 | AJ11: 19800 | AK11: 19800 | AL11: 19800 | AM11: 19800 | AN11: 19800 | AO11: 19800 | AP11: 19800 | AQ11: 19800 | AR11: 19800 | AS11: 19800 | AT11: 19800 | AU11: 19800 | AV11: 19800 | AW11: 19800 | AX11: 19800 | AY11: 19800 | AZ11: 19800 | BA11: 19800 | BB11: 19800 | BC11: 19800 | BD11: 19800 | BE11: 19800 | BF11: 19800 | BG11: 19800 | BH11: 19800 | BI11: 19800 | BJ11: 19800 | BK11: 19800 | BL11: 19800 | BM11: 19800 | BN11: 19800 | BO11: 19800 | BP11: 19800 | BQ11: 19800 | BR11: 19800
C12: アカウント数 | F12: =F14*F17+F15*F17*F16 -> 0 | G12: =G14*G17+G15*G17*G16 -> 1.8018256 | H12: =H14*H17+H15*H17*H16 -> 10.774917 | I12: =I14*I17+I15*I17*I16 -> 19.568546 | J12: =J14*J17+J15*J17*J16 -> 28.186303 | K12: =K14*K17+K15*K17*K16 -> 38.433531 | L12: =L14*L17+L15*L17*L16 -> 48.475813 | M12: =M14*M17+M15*M17*M16 -> 58.31725 | ... BM12: =BM14*BM17+BM15*BM17*BM16 -> 1137.7344 | BN12: =Q12 -> 104.54946 | BO12: =AC12 -> 274.35954 | BP12: =AO12 -> 505.70145 | BQ12: =BQ14*BQ17+BQ15*BQ17*BQ16 -> 778.36853 | BR12: =BR14*BR17+BR15*BR17*BR16 -> 1137.7344
C13: 税理士登録者 | D13: 82276 | F13: 0.99964753 | G13: 0.99964753 | H13: 0.99964753 | I13: 0.99964753 | J13: 0.99964753 | K13: 0.99964753 | L13: 0.99964753 | M13: 0.99964753 | N13: 0.99964753 | O13: 0.99964753 | P13: 0.99964753 | Q13: 0.99964753 | R13: 0.99964753 | S13: 0.99964753 | T13: 0.99964753 | U13: 0.99964753 | V13: 0.99964753 | W13: 0.99964753 | X13: 0.99964753 | Y13: 0.99964753 | Z13: 0.99964753 | AA13: 0.99964753 | AB13: 0.99964753 | AC13: 0.99964753 | AD13: 0.99964753 | AE13: 0.99964753 | AF13: 0.99964753 | AG13: 0.99964753 | AH13: 0.99964753 | AI13: 0.99964753 | AJ13: 0.99964753 | AK13: 0.99964753 | AL13: 0.99964753 | AM13: 0.99964753 | AN13: 0.99964753 | AO13: 0.99964753 | AP13: 0.99964753 | AQ13: 0.99964753 | AR13: 0.99964753 | AS13: 0.99964753 | AT13: 0.99964753 | AU13: 0.99964753 | AV13: 0.99964753 | AW13: 0.99964753 | AX13: 0.99964753 | AY13: 0.99964753 | AZ13: 0.99964753 | BA13: 0.99964753 | BB13: 0.99964753 | BC13: 0.99964753 | BD13: 0.99964753 | BE13: 0.99964753 | BF13: 0.99964753 | BG13: 0.99964753 | BH13: 0.99964753 | BI13: 0.99964753 | BJ13: 0.99964753 | BK13: 0.99964753 | BL13: 0.99964753 | BM13: 0.99964753 | BN13: 0.99964753 | BO13: 0.99964753 | BP13: 0.99964753 | BQ13: 0.99964753 | BR13: 0.99964753
C14: ├ 開業税理士（個人事務所の所長） | D14: 55847 | F14: 0.67877631 | G14: 0.67877631 | H14: 0.67877631 | I14: 0.67877631 | J14: 0.67877631 | K14: 0.67877631 | L14: 0.67877631 | M14: 0.67877631 | N14: 0.67877631 | O14: 0.67877631 | P14: 0.67877631 | Q14: 0.67877631 | R14: 0.67877631 | S14: 0.67877631 | T14: 0.67877631 | U14: 0.67877631 | V14: 0.67877631 | W14: 0.67877631 | X14: 0.67877631 | Y14: 0.67877631 | Z14: 0.67877631 | AA14: 0.67877631 | AB14: 0.67877631 | AC14: 0.67877631 | AD14: 0.67877631 | AE14: 0.67877631 | AF14: 0.67877631 | AG14: 0.67877631 | AH14: 0.67877631 | AI14: 0.67877631 | AJ14: 0.67877631 | AK14: 0.67877631 | AL14: 0.67877631 | AM14: 0.67877631 | AN14: 0.67877631 | AO14: 0.67877631 | AP14: 0.67877631 | AQ14: 0.67877631 | AR14: 0.67877631 | AS14: 0.67877631 | AT14: 0.67877631 | AU14: 0.67877631 | AV14: 0.67877631 | AW14: 0.67877631 | AX14: 0.67877631 | AY14: 0.67877631 | AZ14: 0.67877631 | BA14: 0.67877631 | BB14: 0.67877631 | BC14: 0.67877631 | BD14: 0.67877631 | BE14: 0.67877631 | BF14: 0.67877631 | BG14: 0.67877631 | BH14: 0.67877631 | BI14: 0.67877631 | BJ14: 0.67877631 | BK14: 0.67877631 | BL14: 0.67877631 | BM14: 0.67877631 | BN14: 0.67877631 | BO14: 0.67877631 | BP14: 0.67877631 | BQ14: 0.67877631 | BR14: 0.67877631
C15: ├ うち法人・勤務系 | D15: 26400 | F15: 0.32087121 | G15: 0.32087121 | H15: 0.32087121 | I15: 0.32087121 | J15: 0.32087121 | K15: 0.32087121 | L15: 0.32087121 | M15: 0.32087121 | N15: 0.32087121 | O15: 0.32087121 | P15: 0.32087121 | Q15: 0.32087121 | R15: 0.32087121 | S15: 0.32087121 | T15: 0.32087121 | U15: 0.32087121 | V15: 0.32087121 | W15: 0.32087121 | X15: 0.32087121 | Y15: 0.32087121 | Z15: 0.32087121 | AA15: 0.32087121 | AB15: 0.32087121 | AC15: 0.32087121 | AD15: 0.32087121 | AE15: 0.32087121 | AF15: 0.32087121 | AG15: 0.32087121 | AH15: 0.32087121 | AI15: 0.32087121 | AJ15: 0.32087121 | AK15: 0.32087121 | AL15: 0.32087121 | AM15: 0.32087121 | AN15: 0.32087121 | AO15: 0.32087121 | AP15: 0.32087121 | AQ15: 0.32087121 | AR15: 0.32087121 | AS15: 0.32087121 | AT15: 0.32087121 | AU15: 0.32087121 | AV15: 0.32087121 | AW15: 0.32087121 | AX15: 0.32087121 | AY15: 0.32087121 | AZ15: 0.32087121 | BA15: 0.32087121 | BB15: 0.32087121 | BC15: 0.32087121 | BD15: 0.32087121 | BE15: 0.32087121 | BF15: 0.32087121 | BG15: 0.32087121 | BH15: 0.32087121 | BI15: 0.32087121 | BJ15: 0.32087121 | BK15: 0.32087121 | BL15: 0.32087121 | BM15: 0.32087121 | BN15: 0.32087121 | BO15: 0.32087121 | BP15: 0.32087121 | BQ15: 0.32087121 | BR15: 0.32087121
C16: └ 法人拠点あたり税理士 | D16: 3.5 | F16: 3.5 | G16: 3.5 | H16: 3.5 | I16: 3.5 | J16: 3.5 | K16: 3.5 | L16: 3.5 | M16: 3.5 | N16: 3.5 | O16: 3.5 | P16: 3.5 | Q16: 3.5 | R16: 3.5 | S16: 3.5 | T16: 3.5 | U16: 3.5 | V16: 3.5 | W16: 3.5 | X16: 3.5 | Y16: 3.5 | Z16: 3.5 | AA16: 3.5 | AB16: 3.5 | AC16: 3.5 | AD16: 3.5 | AE16: 3.5 | AF16: 3.5 | AG16: 3.5 | AH16: 3.5 | AI16: 3.5 | AJ16: 3.5 | AK16: 3.5 | AL16: 3.5 | AM16: 3.5 | AN16: 3.5 | AO16: 3.5 | AP16: 3.5 | AQ16: 3.5 | AR16: 3.5 | AS16: 3.5 | AT16: 3.5 | AU16: 3.5 | AV16: 3.5 | AW16: 3.5 | AX16: 3.5 | AY16: 3.5 | AZ16: 3.5 | BA16: 3.5 | BB16: 3.5 | BC16: 3.5 | BD16: 3.5 | BE16: 3.5 | BF16: 3.5 | BG16: 3.5 | BH16: 3.5 | BI16: 3.5 | BJ16: 3.5 | BK16: 3.5 | BL16: 3.5 | BM16: 3.5 | BN16: 3.5 | BO16: 3.5 | BP16: 3.5 | BQ16: 3.5 | BR16: 3.5
C17: 契約事務所 | F17: =(E17*(1-F20))+F18 -> 0 | G17: =(F17*(1-G20))+G18 -> 1 | H17: =(G17*(1-H20))+H18 -> 5.98 | I17: =(H17*(1-I20))+I18 -> 10.8604 | J17: =(I17*(1-J20))+J18 -> 15.643192 | K17: =(J17*(1-K20))+K18 -> 21.330328 | L17: =(K17*(1-L20))+L18 -> 26.903722 | M17: =(L17*(1-M20))+M18 -> 32.365647 | ... BM17: =(BL17*(1-BM20))+BM18 -> 631.43429 | BN17: =Q17 -> 58.024186 | BO17: =AC17 -> 152.26753 | BP17: =AO17 -> 280.6606 | BQ17: =BA17 -> 431.98884 | BR17: =BM17 -> 631.43429
C18: 新規 | F18: 0 | G18: 1 | H18: 5 | I18: 5 | J18: 5 | K18: =H18+1 -> 6 | L18: =I18+1 -> 6 | M18: =J18+1 -> 6 | N18: =K18+1 -> 7 | O18: =L18+1 -> 7 | P18: =M18+1 -> 7 | Q18: =N18+1 -> 8 | R18: =O18+1 -> 8 | ... BM18: =BJ18+1 -> 24 | BN18: =SUM(F18:Q18) -> 63 | BO18: =SUM(R18:AC18) -> 118 | BP18: =SUM(AD18:AO18) -> 166 | BQ18: =SUM(AP18:BA18) -> 214 | BR18: =SUM(BB18:BM18) -> 262
C19: 解約 | F19: =F17*F20 -> 0 | G19: =G17*G20 -> 0.02 | H19: =H17*H20 -> 0.1196 | I19: =I17*I20 -> 0.217208 | J19: =J17*J20 -> 0.31286384 | K19: =K17*K20 -> 0.42660656 | L19: =L17*L20 -> 0.53807443 | M19: =M17*M20 -> 0.64731294 | ... BM19: =BM17*BM20 -> 6.3143429 | BN19: =SUM(F19:Q19) -> 6.1362973 | BO19: =SUM(R19:AC19) -> 25.641518 | BP19: =SUM(AD19:AO19) -> 39.532829 | BQ19: =SUM(AP19:BA19) -> 64.941686 | BR19: =SUM(BB19:BM19) -> 64.549009
C20: 解約率 | D20: F&M オフィスステーション1.01% | F20: 0.02 | G20: 0.02 | H20: 0.02 | I20: 0.02 | J20: 0.02 | K20: 0.02 | L20: 0.02 | M20: 0.02 | N20: 0.02 | O20: 0.02 | P20: 0.02 | Q20: 0.02 | R20: 0.02 | S20: 0.02 | T20: 0.02 | U20: 0.02 | V20: 0.02 | W20: 0.02 | X20: 0.02 | Y20: 0.02 | Z20: 0.02 | AA20: 0.02 | AB20: 0.02 | AC20: 0.02 | AD20: 0.015 | AE20: 0.015 | AF20: 0.015 | AG20: 0.015 | AH20: 0.015 | AI20: 0.015 | AJ20: 0.015 | AK20: 0.015 | AL20: 0.015 | AM20: 0.015 | AN20: 0.015 | AO20: 0.015 | AP20: 0.015 | AQ20: 0.015 | AR20: 0.015 | AS20: 0.015 | AT20: 0.015 | AU20: 0.015 | AV20: 0.015 | AW20: 0.015 | AX20: 0.015 | AY20: 0.015 | AZ20: 0.015 | BA20: 0.015 | BB20: 0.01 | BC20: 0.01 | BD20: 0.01 | BE20: 0.01 | BF20: 0.01 | BG20: 0.01 | BH20: 0.01 | BI20: 0.01 | BJ20: 0.01 | BK20: 0.01 | BL20: 0.01 | BM20: 0.01 | BN20: =BN19/(BN19+BN17) -> 0.095639823 | BO20: =BO19/(BO19+BO17) -> 0.14412711 | BP20: =BP19/(BP19+BP17) -> 0.12346546 | BQ20: =BQ19/(BQ19+BQ17) -> 0.13068565 | BR20: =BR19/(BR19+BR17) -> 0.092745055
C24: 原価
C25: サーバー・DB費 | D25: Railway/Supabase→スケールで段階増。推定 | F25: 50000 | G25: 50000 | H25: 50000 | I25: 50000 | J25: 50000 | K25: 50000 | L25: 50000 | M25: 50000 | N25: 50000 | O25: 50000 | P25: 50000 | Q25: 50000 | R25: 150000 | S25: 150000 | T25: 150000 | U25: 150000 | V25: 150000 | W25: 150000 | X25: 150000 | Y25: 150000 | Z25: 150000 | AA25: 150000 | AB25: 150000 | AC25: 150000 | AD25: 300000 | AE25: 300000 | AF25: 300000 | AG25: 300000 | AH25: 300000 | AI25: 300000 | AJ25: 300000 | AK25: 300000 | AL25: 300000 | AM25: 300000 | AN25: 300000 | AO25: 300000 | AP25: 500000 | AQ25: 500000 | AR25: 500000 | AS25: 500000 | AT25: 500000 | AU25: 500000 | AV25: 500000 | AW25: 500000 | AX25: 500000 | AY25: 500000 | AZ25: 500000 | BA25: 500000 | BB25: 800000 | BC25: 800000 | BD25: 800000 | BE25: 800000 | BF25: 800000 | BG25: 800000 | BH25: 800000 | BI25: 800000 | BJ25: 800000 | BK25: 800000 | BL25: 800000 | BM25: 800000 | BN25: =SUM(F25:Q25) -> 600000 | BO25: =SUM(R25:AC25) -> 1800000 | BP25: =SUM(AD25:AO25) -> 3600000 | BQ25: =SUM(AP25:BA25) -> 6000000 | BR25: =SUM(BB25:BM25) -> 9600000
C26: 決済手数料 | D26: Stripe 3.6%×SaaS売上 | F26: =F5*0.036 -> 0 | G26: =G5*0.036 -> 1543.5413 | H26: =H5*0.036 -> 9230.3767 | I26: =I5*0.036 -> 16763.476 | J26: =J5*0.036 -> 24145.912 | K26: =K5*0.036 -> 32924.242 | L26: =L5*0.036 -> 41527.004 | M26: =M5*0.036 -> 49957.712 | ... BM26: =BM5*0.036 -> 974644.87 | BN26: =SUM(F26:Q26) -> 473581.4 | BO26: =SUM(R26:AC26) -> 1978937.1 | BP26: =SUM(AD26:AO26) -> 4068036.8 | BQ26: =SUM(AP26:BA26) -> 6682678.2 | BR26: =SUM(BB26:BM26) -> 9963405.8
C27: コンサル直接経費 | D27: 交通費・資料等 コンサル売上の5%。推定 | F27: ='事業・組織再生コンサル'!F4*0.05 -> 0 | G27: ='事業・組織再生コンサル'!G4*0.05 -> 0 | H27: ='事業・組織再生コンサル'!H4*0.05 -> 0 | I27: ='事業・組織再生コンサル'!I4*0.05 -> 0 | J27: ='事業・組織再生コンサル'!J4*0.05 -> 0 | K27: ='事業・組織再生コンサル'!K4*0.05 -> 0 | L27: ='事業・組織再生コンサル'!L4*0.05 -> 16500 | M27: ='事業・組織再生コンサル'!M4*0.05 -> 33000 | ... BM27: ='事業・組織再生コンサル'!BM4*0.05 -> 742500 | BN27: =SUM(F27:Q27) -> 313500 | BO27: =SUM(R27:AC27) -> 1897500 | BP27: =SUM(AD27:AO27) -> 3795000 | BQ27: =SUM(AP27:BA27) -> 5758500 | BR27: =SUM(BB27:BM27) -> 7887000
C28: COGS合計 | F28: =SUM(F24:F27) -> 50000 | G28: =SUM(G24:G27) -> 51543.541 | H28: =SUM(H24:H27) -> 59230.377 | I28: =SUM(I24:I27) -> 66763.476 | J28: =SUM(J24:J27) -> 74145.912 | K28: =SUM(K24:K27) -> 82924.242 | L28: =SUM(L24:L27) -> 108027 | M28: =SUM(M24:M27) -> 132957.71 | ... BM28: =SUM(BM24:BM27) -> 2517144.9 | BN28: =SUM(F28:Q28) -> 1387081.4 | BO28: =SUM(R28:AC28) -> 5676437.1 | BP28: =SUM(AD28:AO28) -> 11463037 | BQ28: =SUM(AP28:BA28) -> 18441178 | BR28: =SUM(BB28:BM28) -> 27450406
C33: 役員報酬
C34: 給与手当
C35: 賞与手当
C36: 法定福利費
C37: 福利厚生費
C38: 採用教育費
C39: 広告宣伝費
C40: 荷造包装費
C41: 外注費
C42: 交際費
C43: 会議費
C44: 旅費交通費
... C60: 雑費

Sheet 事業・組織再生コンサル
C3: 指標 | D3: メモ | F3: M1 | G3: M2 | H3: M3 | I3: M4 | J3: M5 | K3: M6 | L3: M7 | M3: M8 | N3: M9 | O3: M10 | P3: M11 | Q3: M12 | R3: M13 | S3: M1４ | T3: M15 | U3: M16 | V3: M17 | W3: M18 | X3: M19 | Y3: M20 | Z3: M21 | AA3: M22 | AB3: M23 | AC3: M24 | AD3: M25 | AE3: M26 | AF3: M27 | AG3: M28 | AH3: M29 | AI3: M30 | AJ3: M31 | AK3: M32 | AL3: M33 | AM3: M34 | AN3: M35 | AO3: M36 | AP3: M37 | AQ3: M38 | AR3: M39 | AS3: M40 | AT3: M41 | AU3: M42 | AV3: M43 | AW3: M44 | AX3: M45 | AY3: M46 | AZ3: M47 | BA3: M48 | BB3: M49 | BC3: M50 | BD3: M51 | BE3: M52 | BF3: M53 | BG3: M54 | BH3: M55 | BI3: M56 | BJ3: M57 | BK3: M58 | BL3: M59 | BM3: M60 | BN3: Y0 | BO3: Y2 | BP3: Y3 | BQ3: Y4 | BR3: Y5
C4: コンサル売上 | F4: =F6*F9 -> 0 | G4: =G6*G9 -> 0 | H4: =H6*H9 -> 0 | I4: =I6*I9 -> 0 | J4: =J6*J9 -> 0 | K4: =K6*K9 -> 0 | L4: =L6*L9 -> 330000 | M4: =M6*M9 -> 660000 | ... BM4: =BM6*BM9 -> 14850000 | BN4: =SUM(F4:Q4) -> 6270000 | BO4: =SUM(R4:AC4) -> 37950000 | BP4: =SUM(AD4:AO4) -> 75900000 | BQ4: =SUM(AP4:BA4) -> 115170000 | BR4: =SUM(BB4:BM4) -> 157740000
C5: 提案獲得LT（ヶ月） | F5: 3 | G5: 3 | H5: 3 | I5: 3 | J5: 3 | K5: 3 | L5: 3 | M5: 3 | N5: 3 | O5: 3 | P5: 3 | Q5: 3 | R5: 3 | S5: 3 | T5: 3 | U5: 3 | V5: 3 | W5: 3 | X5: 3 | Y5: 3 | Z5: 3 | AA5: 3 | AB5: 3 | AC5: 3 | AD5: 3 | AE5: 3 | AF5: 3 | AG5: 3 | AH5: 3 | AI5: 3 | AJ5: 3 | AK5: 3 | AL5: 3 | AM5: 3 | AN5: 3 | AO5: 3 | AP5: 3 | AQ5: 3 | AR5: 3 | AS5: 3 | AT5: 3 | AU5: 3 | AV5: 3 | AW5: 3 | AX5: 3 | AY5: 3 | AZ5: 3 | BA5: 3 | BB5: 3 | BC5: 3 | BD5: 3 | BE5: 3 | BF5: 3 | BG5: 3 | BH5: 3 | BI5: 3 | BJ5: 3 | BK5: 3 | BL5: 3 | BM5: 3 | BN5: 3 | BO5: 3 | BP5: 3 | BQ5: 3 | BR5: 3
C6: コンサル単価 | F6: 330000 | G6: 330000 | H6: 330000 | I6: 330000 | J6: 330000 | K6: 330000 | L6: 330000 | M6: 330000 | N6: 330000 | O6: 330000 | P6: 330000 | Q6: 330000 | R6: 330000 | S6: 330000 | T6: 330000 | U6: 330000 | V6: 330000 | W6: 330000 | X6: 330000 | Y6: 330000 | Z6: 330000 | AA6: 330000 | AB6: 330000 | AC6: 330000 | AD6: 330000 | AE6: 330000 | AF6: 330000 | AG6: 330000 | AH6: 330000 | AI6: 330000 | AJ6: 330000 | AK6: 330000 | AL6: 330000 | AM6: 330000 | AN6: 330000 | AO6: 330000 | AP6: 330000 | AQ6: 330000 | AR6: 330000 | AS6: 330000 | AT6: 330000 | AU6: 330000 | AV6: 330000 | AW6: 330000 | AX6: 330000 | AY6: 330000 | AZ6: 330000 | BA6: 330000 | BB6: 330000 | BC6: 330000 | BD6: 330000 | BE6: 330000 | BF6: 330000 | BG6: 330000 | BH6: 330000 | BI6: 330000 | BJ6: 330000 | BK6: 330000 | BL6: 330000 | BM6: 330000 | BN6: 330000 | BO6: 330000 | BP6: 330000 | BQ6: 330000 | BR6: 330000
C7: 契約コンサル案件 | F7: =E7-F11+F8 -> 0 | G7: =F7-G11+G8 -> 0 | H7: =G7-H11+H8 -> 0 | I7: =H7-I11+I8 -> 0 | J7: =I7-J11+J8 -> 0.1365 | K7: =J7-K11+K8 -> 0.812175 | L7: =K7-L11+L8 -> 1.4540662 | M7: =L7-M11+M8 -> 2.0638629 | ... BM7: =BL7-BM11+BM8 -> 44.94101 | BN7: =Q7 -> 4.8559169 | BO7: =AC7 -> 13.969548 | BP7: =AO7 -> 23.913458 | BQ7: =BA7 -> 34.306018 | BR7: =BM7 -> 44.94101
C8: 新規契約コンサル案件 | F8: =F12*F13 -> 0 | G8: =G12*G13 -> 0 | H8: =H12*H13 -> 0 | I8: =I12*I13 -> 0 | J8: =J12*J13 -> 0.1365 | K8: =K12*K13 -> 0.6825 | L8: =L12*L13 -> 0.6825 | M8: =M12*M13 -> 0.6825 | ... BM8: =BM12*BM13 -> 3.1395 | BN8: =SUM(F8:Q8) -> 5.5965 | BO8: =SUM(R8:AC8) -> 14.469 | BP8: =SUM(AD8:AO8) -> 21.021 | BQ8: =SUM(AP8:BA8) -> 27.573 | BR8: =SUM(BB8:BM8) -> 34.125
C9: 新規契約コンサル案件(本イキ) | F9: 0 | G9: 0 | H9: 0 | I9: 0 | J9: 0 | K9: 0 | L9: 1 | M9: 2 | N9: 3 | O9: 4 | P9: 4 | Q9: 5 | R9: 5 | S9: 6 | T9: 7 | U9: 8 | V9: 8 | W9: 9 | X9: 10 | Y9: 11 | Z9: 12 | AA9: 12 | AB9: 13 | AC9: 14 | AD9: 15 | AE9: 15 | AF9: 16 | AG9: 17 | AH9: 18 | AI9: 19 | AJ9: 20 | AK9: 20 | AL9: 21 | AM9: 22 | AN9: 23 | AO9: 24 | AP9: 24 | AQ9: 25 | AR9: 26 | AS9: 27 | AT9: 28 | AU9: 29 | AV9: 30 | AW9: 30 | AX9: 31 | AY9: 32 | AZ9: 33 | BA9: 34 | BB9: 35 | BC9: 36 | BD9: 37 | BE9: 38 | BF9: 38 | BG9: 39 | BH9: 40 | BI9: 41 | BJ9: 42 | BK9: 43 | BL9: 44 | BM9: 45
C10: 解約率 | D10: 株式会社承知いたしました一年後解約率 | F10: 0.05 | G10: 0.05 | H10: 0.05 | I10: 0.05 | J10: 0.05 | K10: 0.05 | L10: 0.05 | M10: 0.05 | N10: 0.05 | O10: 0.05 | P10: 0.05 | Q10: 0.05 | R10: 0.05 | S10: 0.05 | T10: 0.05 | U10: 0.05 | V10: 0.05 | W10: 0.05 | X10: 0.05 | Y10: 0.05 | Z10: 0.05 | AA10: 0.05 | AB10: 0.05 | AC10: 0.05 | AD10: 0.05 | AE10: 0.05 | AF10: 0.05 | AG10: 0.05 | AH10: 0.05 | AI10: 0.05 | AJ10: 0.05 | AK10: 0.05 | AL10: 0.05 | AM10: 0.05 | AN10: 0.05 | AO10: 0.05 | AP10: 0.05 | AQ10: 0.05 | AR10: 0.05 | AS10: 0.05 | AT10: 0.05 | AU10: 0.05 | AV10: 0.05 | AW10: 0.05 | AX10: 0.05 | AY10: 0.05 | AZ10: 0.05 | BA10: 0.05 | BB10: 0.05 | BC10: 0.05 | BD10: 0.05 | BE10: 0.05 | BF10: 0.05 | BG10: 0.05 | BH10: 0.05 | BI10: 0.05 | BJ10: 0.05 | BK10: 0.05 | BL10: 0.05 | BM10: 0.05 | BN10: =BN11/(BN7+BN8) -> 0.070852811 | BO10: =BO11/(BO7+BO8) -> 0.18831374 | BP10: =BP11/(BP7+BP8) -> 0.2465166 | BQ10: =BQ11/(BQ7+BQ8) -> 0.27764565 | BR10: =BR11/(BR7+BR8) -> 0.29709362
C11: 解約数 | F11: =E7*(F10) -> 0 | G11: =F7*(G10) -> 0 | H11: =G7*(H10) -> 0 | I11: =H7*(I10) -> 0 | J11: =I7*(J10) -> 0 | K11: =J7*(K10) -> 0.006825 | L11: =K7*(L10) -> 0.04060875 | M11: =L7*(M10) -> 0.072703313 | ... BM11: =BL7*(BM10) -> 2.2000795 | BN11: =SUM(F11:Q11) -> 0.74058311 | BO11: =SUM(R11:AC11) -> 5.3553692 | BP11: =SUM(AD11:AO11) -> 11.07709 | BQ11: =SUM(AP11:BA11) -> 17.18044 | BR11: =SUM(BB11:BM11) -> 23.490008
C12: 受注率 | D12: 株式会社承知いたしました受注率２０％ | F12: 0.05 | G12: 0.05 | H12: 0.05 | I12: 0.05 | J12: 0.05 | K12: 0.05 | L12: 0.05 | M12: 0.05 | N12: 0.05 | O12: 0.05 | P12: 0.05 | Q12: 0.05 | R12: 0.05 | S12: 0.05 | T12: 0.05 | U12: 0.05 | V12: 0.05 | W12: 0.05 | X12: 0.05 | Y12: 0.05 | Z12: 0.05 | AA12: 0.05 | AB12: 0.05 | AC12: 0.05 | AD12: 0.05 | AE12: 0.05 | AF12: 0.05 | AG12: 0.05 | AH12: 0.05 | AI12: 0.05 | AJ12: 0.05 | AK12: 0.05 | AL12: 0.05 | AM12: 0.05 | AN12: 0.05 | AO12: 0.05 | AP12: 0.05 | AQ12: 0.05 | AR12: 0.05 | AS12: 0.05 | AT12: 0.05 | AU12: 0.05 | AV12: 0.05 | AW12: 0.05 | AX12: 0.05 | AY12: 0.05 | AZ12: 0.05 | BA12: 0.05 | BB12: 0.05 | BC12: 0.05 | BD12: 0.05 | BE12: 0.05 | BF12: 0.05 | BG12: 0.05 | BH12: 0.05 | BI12: 0.05 | BJ12: 0.05 | BK12: 0.05 | BL12: 0.05 | BM12: 0.05 | BN12: 0.05 | BO12: 0.05 | BP12: 0.05 | BQ12: 0.05 | BR12: 0.05
